Workbook

Sheet ACCUEIL
A1: نظام ERP — مخزن مديرية التربية — ولاية البيض
A2: ERP_Academie_v9 | Excel 2010 Compatible | VLOOKUP + SUMPRODUCT
A4: المؤسسة | B4: مديرية التربية لولاية البيض
A5: المصلحة | B5: مصلحة الإدارة والوسائل العامة
A6: المسؤول | B6: ماحي كمال عبد الغني — TAG1801
A7: المؤطرة | B7: دهيني ميمونة (مصلحة الميزانية)
A8: فترة الرصد | B8: 38 يوم عمل (01/02 – 09/03/2026)
A9: الإصدار | B9: v7 | أفريل 2026
A11: مؤشرات الأداء الرئيسية (تُحسب آلياً من MOUVEMENTS)
A12: إجمالي قيمة المخزون (دج) | B12: =SUMIFS(MOUVEMENTS!$E$3:$E$500,MOUVEMENTS!$B$3:$B$500,"ART-001",MOUVEMENTS!$D$3:$D$500,"IN")-SUMIFS(MOUVEMENTS!$E$3:$E$500,MOUVEMENTS!$B$3:$B$500,"ART-001",MOUVEMENTS!$D$3:$D$500,"OUT") | C12: مرجع Wilson: ART-001
A13: مواد في حالة RUPTURE | B13: =COUNTIF('TABLEAU DE BORD'!$K$4:$K$15,"!! RUPTURE") | C13: 12 مادة
A14: مواد تحتاج طلبية عاجلة | B14: =COUNTIF('TABLEAU DE BORD'!$K$4:$K$15,">> COMMANDER") | C14: دخول + خروج
A15: مواد في حالة تنبيه ~ ALERTE | B15: =COUNTIF('TABLEAU DE BORD'!$K$4:$K$15,"~ ALERTE") | C15: تنبيه فوري
A17: WORKFLOW — Raccourcis VBA (ALT+F11 → Macros → Exécuter)
A18: ① AjouterMouvement | B18: Lance le formulaire de saisie (UserForm frmDataEntry)
A19: ② VerifierAlertes | B19: Affiche une MsgBox avec tous les articles en alerte ou rupture
A20: ③ RafraichirTableauBord | B20: Force le recalcul + navigue vers le Tableau de Bord
A21: ④ GenererBonReception | B21: Exporte le dernier bon de réception en PDF horodaté
A22: ⑤ GenererBonSortie | B22: Exporte le dernier bon de sortie (وصل الخروج) en PDF horodaté
A23: ⑥ GenererDA | B23: Crée et exporte une Demande d'Achat (طلب الشراء) vierge en PDF
A24: ⑦ GenererBC | B24: Crée et exporte un Bon de Commande (أمر الشراء) en PDF

Sheet ARTICLES
A1: CATALOGUE DES ARTICLES — مديرية التربية — البيض [v8.1 | 12 articles | Catégorie + Alias]
A2: Code Article | B2: Désignation (FR) | C2: التسمية (AR) | D2: Unité | E2: Cl. ABC | F2: Stock Min | G2: Stock Max | H2: Prix Unit. (DA) | I2: Fournisseur | J2: Emplacement | K2: Catégorie principale | L2: Sous-catégorie | M2: Alias / Noms alternatifs (pour référence uniquement)
A3: ART-001 | B3: Rame papier A4 80g/m² | C3: رزمة ورق A4 80غ | D3: Rame | E3: A | F3: 400 | G3: 1500 | H3: 400 | I3: ENAP Alger | J3: Rayon A-E1 | K3: لوازم مكتبية / Fournitures Bureau | L3: ورق الطباعة / Papier | M3: Rame A4 | papier blanc | ورق مكتبي | white paper
A4: ART-002 | B4: Toner imprimante G030 (noir) | C4: حبر طابعة G030 | D4: Unité | E4: B | F4: 3 | G4: 15 | H4: 3000 | I4: Bureautique Oran | J4: Rayon B-E2 | K4: مستهلكات إعلام آلي / Consommables IT | L4: حبر وتونر / Toner & Encre | M4: Toner HP | حبر ليزر | Toner 6030 | cartouche laser
A5: ART-003 | B5: Rame papier A3 80g/m² | C5: رزمة ورق A3 80غ | D5: Rame | E5: B | F5: 30 | G5: 150 | H5: 600 | I5: ENAP Alger | J5: Rayon A-E3 | K5: لوازم مكتبية / Fournitures Bureau | L5: ورق الطباعة / Papier | M5: Rame A3 | papier A3 | ورق كبير
A6: ART-004 | B6: Boîte archives carton | C6: علبة الأرشيف | D6: Unité | E6: C | F6: 20 | G6: 200 | H6: 150 | I6: Bureau Plus | J6: Rayon C-E1 | K6: أرشيف وتخزين / Archivage | L6: علب وملفات / Boîtes | M6: boîte archive | علبة أرشيف | carton classement
A7: ART-005 | B7: Agrafeuse de bureau | C7: دباسة مكتبية | D7: Unité | E7: C | F7: 2 | G7: 10 | H7: 800 | I7: Bureau Plus | J7: Rayon C-E1 | K7: أدوات مكتبية / Matériel Bureau | L7: تدبيس وربط / Agrafage | M7: agrafeuse | stapler | دباسة كبيرة
A8: ART-006 | B8: Stylos bille boîte/50 | C8: أقلام حبر جاف | D8: Boîte | E8: C | F8: 5 | G8: 30 | H8: 30 | I8: ENAP Alger | J8: Rayon A-E1 | K8: أدوات الكتابة / Écriture | L8: أقلام / Stylos | M8: stylo bille | bic | قلم جاف | pen
A9: ART-007 | B9: Registre grand format 5m | C9: سجل 5م | D9: Unité | E9: C | F9: 2 | G9: 10 | H9: 300 | I9: ENAP Alger | J9: Rayon A-E2 | K9: سجلات إدارية / Registres | L9: دفاتر وسجلات / Cahiers | M9: registre 5m | grand registre | سجل إداري
A10: ART-008 | B10: Encre tampon | C10: حبر الختم | D10: Unité | E10: C | F10: 2 | G10: 10 | H10: 200 | I10: Bureau Plus | J10: Rayon C-E2 | K10: أدوات مكتبية / Matériel Bureau | L10: ختم وطباعة / Tampon | M10: encre tampon | pad ink | حبر الختم الرسمي
A11: ART-009 | B11: Sous-chemise carton | C11: ملف (sous-chemise) | D11: Unité | E11: C | F11: 10 | G11: 100 | H11: 50 | I11: ENAP Alger | J11: Rayon A-E1 | K11: أرشيف وتخزين / Archivage | L11: علب وملفات / Boîtes | M11: sous-chemise | ملف كرتوني | ملف أصفر | chemise carton
A12: ART-010 | B12: Chemise cartonnée | C12: ملف (Chemise) | D12: Unité | E12: C | F12: 5 | G12: 50 | H12: 80 | I12: ENAP Alger | J12: Rayon A-E1 | K12: أرشيف وتخزين / Archivage | L12: علب وملفات / Boîtes | M12: chemise | ملف عادي | ملف A4 | folder
A13: ART-011 | B13: Rouleau papier fax | C13: بكرة الفاكس | D13: Rouleau | E13: C | F13: 1 | G13: 5 | H13: 400 | I13: Bureautique Oran | J13: Rayon B-E3 | K13: مستهلكات إعلام آلي / Consommables IT | L13: فاكس وطابعة / Fax | M13: rouleau fax | papier fax | بكرة الفاكس الحراري
A14: ART-012 | B14: Marqueur permanent noir | C14: قلم تحديد أسود | D14: Unité | E14: C | F14: 5 | G14: 30 | H14: 50 | I14: ENAP Alger | J14: Rayon A-E1 | K14: أدوات الكتابة / Écriture | L14: أقلام / Stylos | M14: marqueur | feutre | قلم ماجيك | marker permanent
A16: 📌 Classe A = forte valeur (contrôle mensuel) | Classe B = intermédiaire (trimestriel) | Classe C = courant (semestriel) | Colonne Alias = noms alternatifs pour référence — NE PAS utiliser pour saisie

Sheet FOURNISSEURS
A1: CATALOGUE DES FOURNISSEURS — Évaluation pondérée (note /10)
A2: Code | B2: Nom abrégé | C2: Raison sociale | D2: Wilaya | E2: Téléphone | F2: Classe | G2: Délai (j) | H2: Note /100 | I2: Spécialité
A3: F-001 | B3: ENAP Alger | C3: Entreprise Nat. des Arts et Papeteries | D3: Alger | E3: 021-XX-XX-XX | F3: A | G3: 8 | H3: 95 | I3: Articles papeterie, impression
A4: F-002 | B4: Bureautique Oran | C4: Fournisseur bureautique multi-services | D4: Oran | E4: 041-XX-XX-XX | F4: A | G4: 5 | H4: 90 | I4: Consommables informatiques, toners
A5: F-003 | B5: Bureau Plus | C5: Articles de bureau et consommables | D5: Mascara | E5: 045-XX-XX-XX | F5: B | G5: 7 | H5: 80 | I5: Matériel de bureau, classement

Sheet CONVENTIONS
A1: CONVENTIONS — قواعد التسمية والترميز | مديرية التربية — ولاية البيض
A2: هذه الورقة تُوثِّق الاصطلاحات المعتمدة في النظام لضمان الاتساق بين جميع الوثائق والمستخدمين. | لا تُعدِّل هذه الأرقام بعد البدء بالاستخدام الفعلي.
A3: ▸ أولاً — ترقيم الوثائق الإدارية
A4: القاعدة العامة: رمز الوثيقة — السنة — الرقم التسلسلي
A5: DA | B5: DA-SSSS-NNN | C5: DA-2026-001 | D5: قاعدة ثابتة / Format : | E5: طلب الاحتياج الداخلي — يصدر عن المصلحة الطالبة قبل أي عملية شراء. SSSS=السنة. NNN=رقم متسلسل يبدأ من 001 كل سنة.
A6: BC | B6: BC-SSSS-NNN | C6: BC-2026-007 | D6: قاعدة ثابتة / Format : | E6: أمر الشراء — يصدر عن المديرية للمورد بعد اعتماد DA. يُحال دائماً لرقم DA في الخانة المخصصة.
A7: BR | B7: BR-SSSS-NNN | C7: BR-2026-003 | D7: قاعدة ثابتة / Format : | E7: وصل الاستلام — يُحرَّر عند وصول البضاعة من المورد. يُحال لرقم BC المقابل. يُحفَظ في ملف اللوازم.
A8: BS | B8: BS-SSSS-NNN | C8: BS-2026-012 | D8: قاعدة ثابتة / Format : | E8: وصل الخروج/الصرف — يُحرَّر عند تسليم المواد للمصلحة الطالبة. يُحال لرقم DA عند الإمكان.
A9: BC_Comp | B9: BC-2026-007-C | C9: — | D9: قاعدة ثابتة / Format : | E9: إضافة حرف C (Complément) لأوامر الشراء التكميلية لنفس الطلبية — نادر الاستخدام.
A11: ▸ ثانياً — ترميز المواد (Code Article)
A12: ART | B12: ART-NNN | C12: ART-001 | D12: قاعدة ثابتة / Format : | E12: كل مادة تأخذ رمزاً فريداً لا يتغير أبداً بعد تسجيلها في النظام. NNN يبدأ من 001 ويزيد بـ 1 لكل مادة جديدة. لا تُعيد استخدام رمز مادة محذوفة.
A13: INC | B13: INC-01 | C13: INC-01 | D13: قاعدة ثابتة / Format : | E13: للمواد غير المعرَّفة أو التي لم تُصنَّف بعد. تُعالَج قبل أي عملية إدخال رسمية.
A15: ▸ ثالثاً — هرمية الفئات (Catégories)
A16: 1 | B16: لوازم مكتبية | C16: Fournitures Bureau | D16: ورق الطباعة | E16: ورق — أقلام — ملفات — دفاتر — سجلات إدارية
A17: 2 | B17: مستهلكات إعلام آلي | C17: Consommables IT | D17: حبر وتونر | E17: تونر الطابعة — خراطيش الحبر — بكرة الفاكس
A18: 3 | B18: أرشيف وتخزين | C18: Archivage & Classement | D18: علب وملفات | E18: علب الأرشيف — الملفات الكرتونية — ملفات A4
A19: 4 | B19: أدوات مكتبية | C19: Matériel Bureau | D19: تدبيس وربط | E19: الدباسة — دبابيس — مشابك — ختم ومساحة
A20: 5 | B20: أدوات الكتابة | C20: Écriture & Dessin | D20: أقلام | E20: قلم جاف — قلم تحديد — قلم ماجيك — ممحاة
A21: 6 | B21: سجلات إدارية | C21: Registres Administratifs | D21: دفاتر وسجلات | E21: سجل 5م — دفتر كبير — دفتر حضور
A23: ▸ رابعاً — قواعد التسمية الرسمية (قاعدة ذهبية)
A24: ★ | B24: التسمية الرسمية (FR): مُحددة، معيارية، تشمل المواصفة التقنية | D24: مثال صحيح: "Rame papier A4 80g/m²" | خاطئ: "ورق أبيض" أو "Rame A4"
A25: ★ | B25: التسمية الرسمية (AR): تُكتَب مرة واحدة فقط في ورقة ARTICLES — لا يُكتَب الاسم يدوياً في أي وثيقة أخرى | D25: الاسم يُجلَب تلقائياً بـ VLOOKUP من رمز المادة
A26: ★ | B26: الأسماء البديلة (Alias): تُوثَّق في العمود 13 من ARTICLES للاسترشاد — لا تُستخدَم للإدخال | D26: مثال: ART-001 → alias: "Rame A4 | papier blanc | ورق مكتبي" — كلها خاطئة للإدخال
A27: ★ | B27: الوحدة: تُحدَّد مرة واحدة في ARTICLES — رزمة / وحدة / علبة / رولو — لا تخلط بين رزمة وقطعة | D27: مثال: ART-001 وحدته Rame (رزمة 500 ورقة) وليس "ورقة" أو "حزمة"
A30: ERP_Academie_v9 | مديرية التربية — ولاية البيض | ماحي كمال عبد الغني — TAG1801 | 02/04/2026

Sheet MOUVEMENTS
A1: REGISTRE DES MOUVEMENTS — ENTRÉES / SORTIES [v7 | OPT-01 range 500 | OPT-02 MAX(1,…) CMUP | FIX-01 no prefix]
A2: Date | B2: Code Article | C2: Désignation (auto) | D2: Type IN/OUT | E2: Quantité | F2: Prix Unit. (DA) [AUTO-VLOOKUP] | G2: Valeur (DA) | H2: Réf. Doc | I2: Prix Cat. (VLOOKUP col I) | J2: Stock Net (IN−OUT col J) | K2: Valeur IN Cumulée (K) | L2: CMUP Exact (L=K÷MAX(1,ΣIN)) [OPT-02] | M2: Notes
A3: 46022 | B3: ART-001 | C3: =IFERROR(VLOOKUP(B3,ARTICLES!$A$3:$G$500,2,0),"—") | D3: IN | E3: 405 | F3: =IFERROR(VLOOKUP(B3,ARTICLES!$A$3:$G$500,7,0),0) | G3: =E3*F3 | H3: SI-2025 | I3: =IFERROR(VLOOKUP(B3,ARTICLES!$A$3:$G$500,7,0),0) | J3: =SUMPRODUCT(($B$3:$B3=B3)*($D$3:$D3="IN")*$E$3:$E3)-SUMPRODUCT(($B$3:$B3=B3)*($D$3:$D3="OUT")*$E$3:$E3) | K3: =SUMPRODUCT(($B$3:$B3=B3)*($D$3:$D3="IN")*$E$3:$E3*$F$3:$F3) | L3: =IFERROR(K3/MAX(1,SUMPRODUCT(($B$3:$B3=B3)*($D$3:$D3="IN")*$E$3:$E3)),IFERROR(VLOOKUP(B3,ARTICLES!$A$3:$G$500,7,0),0)) | M3: رصيد افتتاحي 31/12/2025
A4: 46030 | B4: ART-001 | C4: =IFERROR(VLOOKUP(B4,ARTICLES!$A$3:$G$500,2,0),"—") | D4: OUT | E4: 75 | F4: =IFERROR(VLOOKUP(B4,ARTICLES!$A$3:$G$500,7,0),0) | G4: =E4*F4 | H4: BS-J1-001 | I4: =IFERROR(VLOOKUP(B4,ARTICLES!$A$3:$G$500,7,0),0) | J4: =SUMPRODUCT(($B$3:$B4=B4)*($D$3:$D4="IN")*$E$3:$E4)-SUMPRODUCT(($B$3:$B4=B4)*($D$3:$D4="OUT")*$E$3:$E4) | K4: =SUMPRODUCT(($B$3:$B4=B4)*($D$3:$D4="IN")*$E$3:$E4*$F$3:$F4) | L4: =IFERROR(K4/MAX(1,SUMPRODUCT(($B$3:$B4=B4)*($D$3:$D4="IN")*$E$3:$E4)),IFERROR(VLOOKUP(B4,ARTICLES!$A$3:$G$500,7,0),0)) | M4: مصلحة الرواتب + المستخدمين
A5: 46037 | B5: ART-001 | C5: =IFERROR(VLOOKUP(B5,ARTICLES!$A$3:$G$500,2,0),"—") | D5: OUT | E5: 55 | F5: =IFERROR(VLOOKUP(B5,ARTICLES!$A$3:$G$500,7,0),0) | G5: =E5*F5 | H5: BS-J1-002 | I5: =IFERROR(VLOOKUP(B5,ARTICLES!$A$3:$G$500,7,0),0) | J5: =SUMPRODUCT(($B$3:$B5=B5)*($D$3:$D5="IN")*$E$3:$E5)-SUMPRODUCT(($B$3:$B5=B5)*($D$3:$D5="OUT")*$E$3:$E5) | K5: =SUMPRODUCT(($B$3:$B5=B5)*($D$3:$D5="IN")*$E$3:$E5*$F$3:$F5) | L5: =IFERROR(K5/MAX(1,SUMPRODUCT(($B$3:$B5=B5)*($D$3:$D5="IN")*$E$3:$E5)),IFERROR(VLOOKUP(B5,ARTICLES!$A$3:$G$500,7,0),0)) | M5: مصلحة الموظفين + الامتحانات
A6: 46050 | B6: ART-001 | C6: =IFERROR(VLOOKUP(B6,ARTICLES!$A$3:$G$500,2,0),"—") | D6: OUT | E6: 40 | F6: =IFERROR(VLOOKUP(B6,ARTICLES!$A$3:$G$500,7,0),0) | G6: =E6*F6 | H6: BS-J1-003 | I6: =IFERROR(VLOOKUP(B6,ARTICLES!$A$3:$G$500,7,0),0) | J6: =SUMPRODUCT(($B$3:$B6=B6)*($D$3:$D6="IN")*$E$3:$E6)-SUMPRODUCT(($B$3:$B6=B6)*($D$3:$D6="OUT")*$E$3:$E6) | K6: =SUMPRODUCT(($B$3:$B6=B6)*($D$3:$D6="IN")*$E$3:$E6*$F$3:$F6) | L6: =IFERROR(K6/MAX(1,SUMPRODUCT(($B$3:$B6=B6)*($D$3:$D6="IN")*$E$3:$E6)),IFERROR(VLOOKUP(B6,ARTICLES!$A$3:$G$500,7,0),0)) | M6: عدة مصالح — نهاية يناير
A7: 46054 | B7: ART-002 | C7: =IFERROR(VLOOKUP(B7,ARTICLES!$A$3:$G$500,2,0),"—") | D7: IN | E7: 5 | F7: =IFERROR(VLOOKUP(B7,ARTICLES!$A$3:$G$500,7,0),0) | G7: =E7*F7 | H7: BR-001 | I7: =IFERROR(VLOOKUP(B7,ARTICLES!$A$3:$G$500,7,0),0) | J7: =SUMPRODUCT(($B$3:$B7=B7)*($D$3:$D7="IN")*$E$3:$E7)-SUMPRODUCT(($B$3:$B7=B7)*($D$3:$D7="OUT")*$E$3:$E7) | K7: =SUMPRODUCT(($B$3:$B7=B7)*($D$3:$D7="IN")*$E$3:$E7*$F$3:$F7) | L7: =IFERROR(K7/MAX(1,SUMPRODUCT(($B$3:$B7=B7)*($D$3:$D7="IN")*$E$3:$E7)),IFERROR(VLOOKUP(B7,ARTICLES!$A$3:$G$500,7,0),0)) | M7: وصل استلام — Toner G030
A8: 46054 | B8: ART-003 | C8: =IFERROR(VLOOKUP(B8,ARTICLES!$A$3:$G$500,2,0),"—") | D8: IN | E8: 100 | F8: =IFERROR(VLOOKUP(B8,ARTICLES!$A$3:$G$500,7,0),0) | G8: =E8*F8 | H8: BR-001 | I8: =IFERROR(VLOOKUP(B8,ARTICLES!$A$3:$G$500,7,0),0) | J8: =SUMPRODUCT(($B$3:$B8=B8)*($D$3:$D8="IN")*$E$3:$E8)-SUMPRODUCT(($B$3:$B8=B8)*($D$3:$D8="OUT")*$E$3:$E8) | K8: =SUMPRODUCT(($B$3:$B8=B8)*($D$3:$D8="IN")*$E$3:$E8*$F$3:$F8) | L8: =IFERROR(K8/MAX(1,SUMPRODUCT(($B$3:$B8=B8)*($D$3:$D8="IN")*$E$3:$E8)),IFERROR(VLOOKUP(B8,ARTICLES!$A$3:$G$500,7,0),0)) | M8: وصل استلام — رزمة ورق A3
A9: 46054 | B9: ART-004 | C9: =IFERROR(VLOOKUP(B9,ARTICLES!$A$3:$G$500,2,0),"—") | D9: IN | E9: 240 | F9: =IFERROR(VLOOKUP(B9,ARTICLES!$A$3:$G$500,7,0),0) | G9: =E9*F9 | H9: SI-001 | I9: =IFERROR(VLOOKUP(B9,ARTICLES!$A$3:$G$500,7,0),0) | J9: =SUMPRODUCT(($B$3:$B9=B9)*($D$3:$D9="IN")*$E$3:$E9)-SUMPRODUCT(($B$3:$B9=B9)*($D$3:$D9="OUT")*$E$3:$E9) | K9: =SUMPRODUCT(($B$3:$B9=B9)*($D$3:$D9="IN")*$E$3:$E9*$F$3:$F9) | L9: =IFERROR(K9/MAX(1,SUMPRODUCT(($B$3:$B9=B9)*($D$3:$D9="IN")*$E$3:$E9)),IFERROR(VLOOKUP(B9,ARTICLES!$A$3:$G$500,7,0),0)) | M9: رصيد افتتاحي فيفري
A10: 46054 | B10: ART-005 | C10: =IFERROR(VLOOKUP(B10,ARTICLES!$A$3:$G$500,2,0),"—") | D10: IN | E10: 4 | F10: =IFERROR(VLOOKUP(B10,ARTICLES!$A$3:$G$500,7,0),0) | G10: =E10*F10 | H10: SI-001 | I10: =IFERROR(VLOOKUP(B10,ARTICLES!$A$3:$G$500,7,0),0) | J10: =SUMPRODUCT(($B$3:$B10=B10)*($D$3:$D10="IN")*$E$3:$E10)-SUMPRODUCT(($B$3:$B10=B10)*($D$3:$D10="OUT")*$E$3:$E10) | K10: =SUMPRODUCT(($B$3:$B10=B10)*($D$3:$D10="IN")*$E$3:$E10*$F$3:$F10) | L10: =IFERROR(K10/MAX(1,SUMPRODUCT(($B$3:$B10=B10)*($D$3:$D10="IN")*$E$3:$E10)),IFERROR(VLOOKUP(B10,ARTICLES!$A$3:$G$500,7,0),0)) | M10: رصيد افتتاحي فيفري
A11: 46054 | B11: ART-006 | C11: =IFERROR(VLOOKUP(B11,ARTICLES!$A$3:$G$500,2,0),"—") | D11: IN | E11: 50 | F11: =IFERROR(VLOOKUP(B11,ARTICLES!$A$3:$G$500,7,0),0) | G11: =E11*F11 | H11: SI-001 | I11: =IFERROR(VLOOKUP(B11,ARTICLES!$A$3:$G$500,7,0),0) | J11: =SUMPRODUCT(($B$3:$B11=B11)*($D$3:$D11="IN")*$E$3:$E11)-SUMPRODUCT(($B$3:$B11=B11)*($D$3:$D11="OUT")*$E$3:$E11) | K11: =SUMPRODUCT(($B$3:$B11=B11)*($D$3:$D11="IN")*$E$3:$E11*$F$3:$F11) | L11: =IFERROR(K11/MAX(1,SUMPRODUCT(($B$3:$B11=B11)*($D$3:$D11="IN")*$E$3:$E11)),IFERROR(VLOOKUP(B11,ARTICLES!$A$3:$G$500,7,0),0)) | M11: رصيد افتتاحي فيفري
A12: 46054 | B12: ART-007 | C12: =IFERROR(VLOOKUP(B12,ARTICLES!$A$3:$G$500,2,0),"—") | D12: IN | E12: 3 | F12: =IFERROR(VLOOKUP(B12,ARTICLES!$A$3:$G$500,7,0),0) | G12: =E12*F12 | H12: SI-001 | I12: =IFERROR(VLOOKUP(B12,ARTICLES!$A$3:$G$500,7,0),0) | J12: =SUMPRODUCT(($B$3:$B12=B12)*($D$3:$D12="IN")*$E$3:$E12)-SUMPRODUCT(($B$3:$B12=B12)*($D$3:$D12="OUT")*$E$3:$E12) | K12: =SUMPRODUCT(($B$3:$B12=B12)*($D$3:$D12="IN")*$E$3:$E12*$F$3:$F12) | L12: =IFERROR(K12/MAX(1,SUMPRODUCT(($B$3:$B12=B12)*($D$3:$D12="IN")*$E$3:$E12)),IFERROR(VLOOKUP(B12,ARTICLES!$A$3:$G$500,7,0),0)) | M12: رصيد افتتاحي فيفري
A13: 46054 | B13: ART-008 | C13: =IFERROR(VLOOKUP(B13,ARTICLES!$A$3:$G$500,2,0),"—") | D13: IN | E13: 5 | F13: =IFERROR(VLOOKUP(B13,ARTICLES!$A$3:$G$500,7,0),0) | G13: =E13*F13 | H13: SI-001 | I13: =IFERROR(VLOOKUP(B13,ARTICLES!$A$3:$G$500,7,0),0) | J13: =SUMPRODUCT(($B$3:$B13=B13)*($D$3:$D13="IN")*$E$3:$E13)-SUMPRODUCT(($B$3:$B13=B13)*($D$3:$D13="OUT")*$E$3:$E13) | K13: =SUMPRODUCT(($B$3:$B13=B13)*($D$3:$D13="IN")*$E$3:$E13*$F$3:$F13) | L13: =IFERROR(K13/MAX(1,SUMPRODUCT(($B$3:$B13=B13)*($D$3:$D13="IN")*$E$3:$E13)),IFERROR(VLOOKUP(B13,ARTICLES!$A$3:$G$500,7,0),0)) | M13: رصيد افتتاحي فيفري
A14: 46054 | B14: ART-009 | C14: =IFERROR(VLOOKUP(B14,ARTICLES!$A$3:$G$500,2,0),"—") | D14: IN | E14: 48 | F14: =IFERROR(VLOOKUP(B14,ARTICLES!$A$3:$G$500,7,0),0) | G14: =E14*F14 | H14: SI-001 | I14: =IFERROR(VLOOKUP(B14,ARTICLES!$A$3:$G$500,7,0),0) | J14: =SUMPRODUCT(($B$3:$B14=B14)*($D$3:$D14="IN")*$E$3:$E14)-SUMPRODUCT(($B$3:$B14=B14)*($D$3:$D14="OUT")*$E$3:$E14) | K14: =SUMPRODUCT(($B$3:$B14=B14)*($D$3:$D14="IN")*$E$3:$E14*$F$3:$F14) | L14: =IFERROR(K14/MAX(1,SUMPRODUCT(($B$3:$B14=B14)*($D$3:$D14="IN")*$E$3:$E14)),IFERROR(VLOOKUP(B14,ARTICLES!$A$3:$G$500,7,0),0)) | M14: رصيد افتتاحي فيفري
... A31: 46090 | B31: ART-009 | C31: =IFERROR(VLOOKUP(B31,ARTICLES!$A$3:$G$500,2,0),"—") | D31: OUT | E31: 22 | F31: =IFERROR(VLOOKUP(B31,ARTICLES!$A$3:$G$500,7,0),0) | G31: =E31*F31 | H31: BS-M1-006 | I31: =IFERROR(VLOOKUP(B31,ARTICLES!$A$3:$G$500,7,0),0) | J31: =SUMPRODUCT(($B$3:$B31=B31)*($D$3:$D31="IN")*$E$3:$E31)-SUMPRODUCT(($B$3:$B31=B31)*($D$3:$D31="OUT")*$E$3:$E31) | K31: =SUMPRODUCT(($B$3:$B31=B31)*($D$3:$D31="IN")*$E$3:$E31*$F$3:$F31) | L31: =IFERROR(K31/MAX(1,SUMPRODUCT(($B$3:$B31=B31)*($D$3:$D31="IN")*$E$3:$E31)),IFERROR(VLOOKUP(B31,ARTICLES!$A$3:$G$500,7,0),0)) | M31: !! رصيد حرج → 1 وحدة

Sheet TABLEAU DE BORD
A1: TABLEAU DE BORD — ÉTAT DU STOCK + STATUTS ROP [v7 | 12 articles | OPT-01 range | OPT-02 CMUP | Excel 2010]
A2: SECTION 1 — ÉTAT DU STOCK EN TEMPS RÉEL (ROP dynamique par article | 38 j obs. | LT = 2 j)
A3: Code | B3: Désignation | C3: ABC | D3: Total IN | E3: Total OUT | F3: STOCK ACTUEL | G3: Stock Min | H3: CMUP (DA) | I3: Valeur Stock (DA) | J3: ROP [OPT-01] | K3: Statut | M3: PARAMÈTRES | N3: Valeur
A4: ART-001 | B4: =IFERROR(VLOOKUP(A4,ARTICLES!$A$3:$G$500,2,0),"") | C4: =IFERROR(VLOOKUP(A4,ARTICLES!$A$3:$D$500,4,0),"") | D4: =SUMIFS(MOUVEMENTS!$E$3:$E$500,MOUVEMENTS!$B$3:$B$500,A4,MOUVEMENTS!$D$3:$D$500,"IN") | E4: =SUMIFS(MOUVEMENTS!$E$3:$E$500,MOUVEMENTS!$B$3:$B$500,A4,MOUVEMENTS!$D$3:$D$500,"OUT") | F4: =D4-E4 | G4: =IFERROR(VLOOKUP(A4,ARTICLES!$A$3:$E$500,5,0),0) | H4: =IFERROR(LOOKUP(2,1/(MOUVEMENTS!$B$3:$B$500=A4),MOUVEMENTS!$L$3:$L$500),IFERROR(VLOOKUP(A4,ARTICLES!$A$3:$G$500,7,0),0)) | I4: =F4*H4 | J4: =IFERROR(G4+(SUMIFS(MOUVEMENTS!$E$3:$E$500,MOUVEMENTS!$B$3:$B$500,A4,MOUVEMENTS!$D$3:$D$500,"OUT")/MAX(1,$N$4))*$N$6,G4) | K4: =IF(F4=0,"!! RUPTURE",IF(F4<=J4,">> COMMANDER",IF(F4<=J4*1.25,"~ ALERTE","OK"))) | M4: Jours observation (fixe) | N4: 38
A5: ART-002 | B5: =IFERROR(VLOOKUP(A5,ARTICLES!$A$3:$G$500,2,0),"") | C5: =IFERROR(VLOOKUP(A5,ARTICLES!$A$3:$D$500,4,0),"") | D5: =SUMIFS(MOUVEMENTS!$E$3:$E$500,MOUVEMENTS!$B$3:$B$500,A5,MOUVEMENTS!$D$3:$D$500,"IN") | E5: =SUMIFS(MOUVEMENTS!$E$3:$E$500,MOUVEMENTS!$B$3:$B$500,A5,MOUVEMENTS!$D$3:$D$500,"OUT") | F5: =D5-E5 | G5: =IFERROR(VLOOKUP(A5,ARTICLES!$A$3:$E$500,5,0),0) | H5: =IFERROR(LOOKUP(2,1/(MOUVEMENTS!$B$3:$B$500=A5),MOUVEMENTS!$L$3:$L$500),IFERROR(VLOOKUP(A5,ARTICLES!$A$3:$G$500,7,0),0)) | I5: =F5*H5 | J5: =IFERROR(G5+(SUMIFS(MOUVEMENTS!$E$3:$E$500,MOUVEMENTS!$B$3:$B$500,A5,MOUVEMENTS!$D$3:$D$500,"OUT")/MAX(1,$N$4))*$N$6,G5) | K5: =IF(F5=0,"!! RUPTURE",IF(F5<=J5,">> COMMANDER",IF(F5<=J5*1.25,"~ ALERTE","OK"))) | M5: Période réf. (jours ouvrés) | N5: =$N$4
A6: ART-003 | B6: =IFERROR(VLOOKUP(A6,ARTICLES!$A$3:$G$500,2,0),"") | C6: =IFERROR(VLOOKUP(A6,ARTICLES!$A$3:$D$500,4,0),"") | D6: =SUMIFS(MOUVEMENTS!$E$3:$E$500,MOUVEMENTS!$B$3:$B$500,A6,MOUVEMENTS!$D$3:$D$500,"IN") | E6: =SUMIFS(MOUVEMENTS!$E$3:$E$500,MOUVEMENTS!$B$3:$B$500,A6,MOUVEMENTS!$D$3:$D$500,"OUT") | F6: =D6-E6 | G6: =IFERROR(VLOOKUP(A6,ARTICLES!$A$3:$E$500,5,0),0) | H6: =IFERROR(LOOKUP(2,1/(MOUVEMENTS!$B$3:$B$500=A6),MOUVEMENTS!$L$3:$L$500),IFERROR(VLOOKUP(A6,ARTICLES!$A$3:$G$500,7,0),0)) | I6: =F6*H6 | J6: =IFERROR(G6+(SUMIFS(MOUVEMENTS!$E$3:$E$500,MOUVEMENTS!$B$3:$B$500,A6,MOUVEMENTS!$D$3:$D$500,"OUT")/MAX(1,$N$4))*$N$6,G6) | K6: =IF(F6=0,"!! RUPTURE",IF(F6<=J6,">> COMMANDER",IF(F6<=J6*1.25,"~ ALERTE","OK"))) | M6: Délai livraison LT (jours) | N6: 2
A7: ART-004 | B7: =IFERROR(VLOOKUP(A7,ARTICLES!$A$3:$G$500,2,0),"") | C7: =IFERROR(VLOOKUP(A7,ARTICLES!$A$3:$D$500,4,0),"") | D7: =SUMIFS(MOUVEMENTS!$E$3:$E$500,MOUVEMENTS!$B$3:$B$500,A7,MOUVEMENTS!$D$3:$D$500,"IN") | E7: =SUMIFS(MOUVEMENTS!$E$3:$E$500,MOUVEMENTS!$B$3:$B$500,A7,MOUVEMENTS!$D$3:$D$500,"OUT") | F7: =D7-E7 | G7: =IFERROR(VLOOKUP(A7,ARTICLES!$A$3:$E$500,5,0),0) | H7: =IFERROR(LOOKUP(2,1/(MOUVEMENTS!$B$3:$B$500=A7),MOUVEMENTS!$L$3:$L$500),IFERROR(VLOOKUP(A7,ARTICLES!$A$3:$G$500,7,0),0)) | I7: =F7*H7 | J7: =IFERROR(G7+(SUMIFS(MOUVEMENTS!$E$3:$E$500,MOUVEMENTS!$B$3:$B$500,A7,MOUVEMENTS!$D$3:$D$500,"OUT")/MAX(1,$N$4))*$N$6,G7) | K7: =IF(F7=0,"!! RUPTURE",IF(F7<=J7,">> COMMANDER",IF(F7<=J7*1.25,"~ ALERTE","OK")))
A8: ART-005 | B8: =IFERROR(VLOOKUP(A8,ARTICLES!$A$3:$G$500,2,0),"") | C8: =IFERROR(VLOOKUP(A8,ARTICLES!$A$3:$D$500,4,0),"") | D8: =SUMIFS(MOUVEMENTS!$E$3:$E$500,MOUVEMENTS!$B$3:$B$500,A8,MOUVEMENTS!$D$3:$D$500,"IN") | E8: =SUMIFS(MOUVEMENTS!$E$3:$E$500,MOUVEMENTS!$B$3:$B$500,A8,MOUVEMENTS!$D$3:$D$500,"OUT") | F8: =D8-E8 | G8: =IFERROR(VLOOKUP(A8,ARTICLES!$A$3:$E$500,5,0),0) | H8: =IFERROR(LOOKUP(2,1/(MOUVEMENTS!$B$3:$B$500=A8),MOUVEMENTS!$L$3:$L$500),IFERROR(VLOOKUP(A8,ARTICLES!$A$3:$G$500,7,0),0)) | I8: =F8*H8 | J8: =IFERROR(G8+(SUMIFS(MOUVEMENTS!$E$3:$E$500,MOUVEMENTS!$B$3:$B$500,A8,MOUVEMENTS!$D$3:$D$500,"OUT")/MAX(1,$N$4))*$N$6,G8) | K8: =IF(F8=0,"!! RUPTURE",IF(F8<=J8,">> COMMANDER",IF(F8<=J8*1.25,"~ ALERTE","OK")))
A9: ART-006 | B9: =IFERROR(VLOOKUP(A9,ARTICLES!$A$3:$G$500,2,0),"") | C9: =IFERROR(VLOOKUP(A9,ARTICLES!$A$3:$D$500,4,0),"") | D9: =SUMIFS(MOUVEMENTS!$E$3:$E$500,MOUVEMENTS!$B$3:$B$500,A9,MOUVEMENTS!$D$3:$D$500,"IN") | E9: =SUMIFS(MOUVEMENTS!$E$3:$E$500,MOUVEMENTS!$B$3:$B$500,A9,MOUVEMENTS!$D$3:$D$500,"OUT") | F9: =D9-E9 | G9: =IFERROR(VLOOKUP(A9,ARTICLES!$A$3:$E$500,5,0),0) | H9: =IFERROR(LOOKUP(2,1/(MOUVEMENTS!$B$3:$B$500=A9),MOUVEMENTS!$L$3:$L$500),IFERROR(VLOOKUP(A9,ARTICLES!$A$3:$G$500,7,0),0)) | I9: =F9*H9 | J9: =IFERROR(G9+(SUMIFS(MOUVEMENTS!$E$3:$E$500,MOUVEMENTS!$B$3:$B$500,A9,MOUVEMENTS!$D$3:$D$500,"OUT")/MAX(1,$N$4))*$N$6,G9) | K9: =IF(F9=0,"!! RUPTURE",IF(F9<=J9,">> COMMANDER",IF(F9<=J9*1.25,"~ ALERTE","OK")))
A10: ART-007 | B10: =IFERROR(VLOOKUP(A10,ARTICLES!$A$3:$G$500,2,0),"") | C10: =IFERROR(VLOOKUP(A10,ARTICLES!$A$3:$D$500,4,0),"") | D10: =SUMIFS(MOUVEMENTS!$E$3:$E$500,MOUVEMENTS!$B$3:$B$500,A10,MOUVEMENTS!$D$3:$D$500,"IN") | E10: =SUMIFS(MOUVEMENTS!$E$3:$E$500,MOUVEMENTS!$B$3:$B$500,A10,MOUVEMENTS!$D$3:$D$500,"OUT") | F10: =D10-E10 | G10: =IFERROR(VLOOKUP(A10,ARTICLES!$A$3:$E$500,5,0),0) | H10: =IFERROR(LOOKUP(2,1/(MOUVEMENTS!$B$3:$B$500=A10),MOUVEMENTS!$L$3:$L$500),IFERROR(VLOOKUP(A10,ARTICLES!$A$3:$G$500,7,0),0)) | I10: =F10*H10 | J10: =IFERROR(G10+(SUMIFS(MOUVEMENTS!$E$3:$E$500,MOUVEMENTS!$B$3:$B$500,A10,MOUVEMENTS!$D$3:$D$500,"OUT")/MAX(1,$N$4))*$N$6,G10) | K10: =IF(F10=0,"!! RUPTURE",IF(F10<=J10,">> COMMANDER",IF(F10<=J10*1.25,"~ ALERTE","OK")))
A11: ART-008 | B11: =IFERROR(VLOOKUP(A11,ARTICLES!$A$3:$G$500,2,0),"") | C11: =IFERROR(VLOOKUP(A11,ARTICLES!$A$3:$D$500,4,0),"") | D11: =SUMIFS(MOUVEMENTS!$E$3:$E$500,MOUVEMENTS!$B$3:$B$500,A11,MOUVEMENTS!$D$3:$D$500,"IN") | E11: =SUMIFS(MOUVEMENTS!$E$3:$E$500,MOUVEMENTS!$B$3:$B$500,A11,MOUVEMENTS!$D$3:$D$500,"OUT") | F11: =D11-E11 | G11: =IFERROR(VLOOKUP(A11,ARTICLES!$A$3:$E$500,5,0),0) | H11: =IFERROR(LOOKUP(2,1/(MOUVEMENTS!$B$3:$B$500=A11),MOUVEMENTS!$L$3:$L$500),IFERROR(VLOOKUP(A11,ARTICLES!$A$3:$G$500,7,0),0)) | I11: =F11*H11 | J11: =IFERROR(G11+(SUMIFS(MOUVEMENTS!$E$3:$E$500,MOUVEMENTS!$B$3:$B$500,A11,MOUVEMENTS!$D$3:$D$500,"OUT")/MAX(1,$N$4))*$N$6,G11) | K11: =IF(F11=0,"!! RUPTURE",IF(F11<=J11,">> COMMANDER",IF(F11<=J11*1.25,"~ ALERTE","OK")))
A12: ART-009 | B12: =IFERROR(VLOOKUP(A12,ARTICLES!$A$3:$G$500,2,0),"") | C12: =IFERROR(VLOOKUP(A12,ARTICLES!$A$3:$D$500,4,0),"") | D12: =SUMIFS(MOUVEMENTS!$E$3:$E$500,MOUVEMENTS!$B$3:$B$500,A12,MOUVEMENTS!$D$3:$D$500,"IN") | E12: =SUMIFS(MOUVEMENTS!$E$3:$E$500,MOUVEMENTS!$B$3:$B$500,A12,MOUVEMENTS!$D$3:$D$500,"OUT") | F12: =D12-E12 | G12: =IFERROR(VLOOKUP(A12,ARTICLES!$A$3:$E$500,5,0),0) | H12: =IFERROR(LOOKUP(2,1/(MOUVEMENTS!$B$3:$B$500=A12),MOUVEMENTS!$L$3:$L$500),IFERROR(VLOOKUP(A12,ARTICLES!$A$3:$G$500,7,0),0)) | I12: =F12*H12 | J12: =IFERROR(G12+(SUMIFS(MOUVEMENTS!$E$3:$E$500,MOUVEMENTS!$B$3:$B$500,A12,MOUVEMENTS!$D$3:$D$500,"OUT")/MAX(1,$N$4))*$N$6,G12) | K12: =IF(F12=0,"!! RUPTURE",IF(F12<=J12,">> COMMANDER",IF(F12<=J12*1.25,"~ ALERTE","OK")))
A13: ART-010 | B13: =IFERROR(VLOOKUP(A13,ARTICLES!$A$3:$G$500,2,0),"") | C13: =IFERROR(VLOOKUP(A13,ARTICLES!$A$3:$D$500,4,0),"") | D13: =SUMIFS(MOUVEMENTS!$E$3:$E$500,MOUVEMENTS!$B$3:$B$500,A13,MOUVEMENTS!$D$3:$D$500,"IN") | E13: =SUMIFS(MOUVEMENTS!$E$3:$E$500,MOUVEMENTS!$B$3:$B$500,A13,MOUVEMENTS!$D$3:$D$500,"OUT") | F13: =D13-E13 | G13: =IFERROR(VLOOKUP(A13,ARTICLES!$A$3:$E$500,5,0),0) | H13: =IFERROR(LOOKUP(2,1/(MOUVEMENTS!$B$3:$B$500=A13),MOUVEMENTS!$L$3:$L$500),IFERROR(VLOOKUP(A13,ARTICLES!$A$3:$G$500,7,0),0)) | I13: =F13*H13 | J13: =IFERROR(G13+(SUMIFS(MOUVEMENTS!$E$3:$E$500,MOUVEMENTS!$B$3:$B$500,A13,MOUVEMENTS!$D$3:$D$500,"OUT")/MAX(1,$N$4))*$N$6,G13) | K13: =IF(F13=0,"!! RUPTURE",IF(F13<=J13,">> COMMANDER",IF(F13<=J13*1.25,"~ ALERTE","OK")))
A14: ART-011 | B14: =IFERROR(VLOOKUP(A14,ARTICLES!$A$3:$G$500,2,0),"") | C14: =IFERROR(VLOOKUP(A14,ARTICLES!$A$3:$D$500,4,0),"") | D14: =SUMIFS(MOUVEMENTS!$E$3:$E$500,MOUVEMENTS!$B$3:$B$500,A14,MOUVEMENTS!$D$3:$D$500,"IN") | E14: =SUMIFS(MOUVEMENTS!$E$3:$E$500,MOUVEMENTS!$B$3:$B$500,A14,MOUVEMENTS!$D$3:$D$500,"OUT") | F14: =D14-E14 | G14: =IFERROR(VLOOKUP(A14,ARTICLES!$A$3:$E$500,5,0),0) | H14: =IFERROR(LOOKUP(2,1/(MOUVEMENTS!$B$3:$B$500=A14),MOUVEMENTS!$L$3:$L$500),IFERROR(VLOOKUP(A14,ARTICLES!$A$3:$G$500,7,0),0)) | I14: =F14*H14 | J14: =IFERROR(G14+(SUMIFS(MOUVEMENTS!$E$3:$E$500,MOUVEMENTS!$B$3:$B$500,A14,MOUVEMENTS!$D$3:$D$500,"OUT")/MAX(1,$N$4))*$N$6,G14) | K14: =IF(F14=0,"!! RUPTURE",IF(F14<=J14,">> COMMANDER",IF(F14<=J14*1.25,"~ ALERTE","OK")))
A15: ART-012 | B15: =IFERROR(VLOOKUP(A15,ARTICLES!$A$3:$G$500,2,0),"") | C15: =IFERROR(VLOOKUP(A15,ARTICLES!$A$3:$D$500,4,0),"") | D15: =SUMIFS(MOUVEMENTS!$E$3:$E$500,MOUVEMENTS!$B$3:$B$500,A15,MOUVEMENTS!$D$3:$D$500,"IN") | E15: =SUMIFS(MOUVEMENTS!$E$3:$E$500,MOUVEMENTS!$B$3:$B$500,A15,MOUVEMENTS!$D$3:$D$500,"OUT") | F15: =D15-E15 | G15: =IFERROR(VLOOKUP(A15,ARTICLES!$A$3:$E$500,5,0),0) | H15: =IFERROR(LOOKUP(2,1/(MOUVEMENTS!$B$3:$B$500=A15),MOUVEMENTS!$L$3:$L$500),IFERROR(VLOOKUP(A15,ARTICLES!$A$3:$G$500,7,0),0)) | I15: =F15*H15 | J15: =IFERROR(G15+(SUMIFS(MOUVEMENTS!$E$3:$E$500,MOUVEMENTS!$B$3:$B$500,A15,MOUVEMENTS!$D$3:$D$500,"OUT")/MAX(1,$N$4))*$N$6,G15) | K15: =IF(F15=0,"!! RUPTURE",IF(F15<=J15,">> COMMANDER",IF(F15<=J15*1.25,"~ ALERTE","OK")))
A17: TOTAUX | F17: =SUM(F4:F16) | I17: =SUM(I4:I16)
A19: LÉGENDE: OK = stock suffisant | ~ ALERTE = stock < 125% du ROP | >> COMMANDER = stock ≤ ROP | !! RUPTURE = stock nul | ROP = Stock_Min + (ΣOuts/38j) × 2j | CMUP = K÷MAX(1,ΣIN) [OPT-02]

Sheet ALERTE_DASHBOARD
A1: ALERTE_DASHBOARD — Sentinelle de Stock [NEW v8 | auto-actualisé par formules]
A2: Les indicateurs ci-dessous se mettent à jour automatiquement à chaque modification de MOUVEMENTS.
A3: Dernière vérification : [Mise à jour par VBA VerifierAlertes — voir colonne O du Guide]
A5: RÉSUMÉ DES ALERTES — COMPTEURS EN TEMPS RÉEL
A6: !! RUPTURES | D6: >> À COMMANDER | G6: ~ EN ALERTE | J6: ✔ NORMAUX
A7: =COUNTIF('TABLEAU DE BORD'!$K$4:$K$15,"!! RUPTURE") | D7: =COUNTIF('TABLEAU DE BORD'!$K$4:$K$15,">> COMMANDER") | G7: =COUNTIF('TABLEAU DE BORD'!$K$4:$K$15,"~ ALERTE") | J7: =COUNTIF('TABLEAU DE BORD'!$K$4:$K$15,"OK")
A8: =COUNTIF('TABLEAU DE BORD'!$K$4:$K$15,"!! RUPTURE")&" / 12 articles" | D8: =COUNTIF('TABLEAU DE BORD'!$K$4:$K$15,">> COMMANDER")&" / 12 articles" | G8: =COUNTIF('TABLEAU DE BORD'!$K$4:$K$15,"~ ALERTE")&" / 12 articles" | J8: =COUNTIF('TABLEAU DE BORD'!$K$4:$K$15,"OK")&" / 12 articles"
A10: DÉTAIL PAR ARTICLE — ÉTAT COMPLET
A11: Code | B11: Désignation | C11: ABC | D11: Stock Actuel | E11: Stock Min | F11: ROP | G11: Statut | H11: CMUP (DA) | I11: Valeur (DA) | J11: Priorité | K11: Action recommandée
A12: ='TABLEAU DE BORD'!A4 | B12: ='TABLEAU DE BORD'!B4 | C12: ='TABLEAU DE BORD'!C4 | D12: ='TABLEAU DE BORD'!F4 | E12: ='TABLEAU DE BORD'!G4 | F12: ='TABLEAU DE BORD'!J4 | G12: ='TABLEAU DE BORD'!K4 | H12: ='TABLEAU DE BORD'!H4 | I12: ='TABLEAU DE BORD'!I4 | J12: =IF('TABLEAU DE BORD'!K4="!! RUPTURE","1 — CRITIQUE",IF('TABLEAU DE BORD'!K4=">> COMMANDER","2 — URGENT",IF('TABLEAU DE BORD'!K4="~ ALERTE","3 — ATTENTION","4 — Normal"))) | K12: =IF('TABLEAU DE BORD'!K4="!! RUPTURE","⛔ BLOQUER sorties — Lancer BC immédiatement",IF('TABLEAU DE BORD'!K4=">> COMMANDER","📋 Émettre BC maintenant (stock ≤ ROP)",IF('TABLEAU DE BORD'!K4="~ ALERTE","⚠ Surveiller — préparer commande sous 3 jours","✔ Aucune action requise")))
A13: ='TABLEAU DE BORD'!A5 | B13: ='TABLEAU DE BORD'!B5 | C13: ='TABLEAU DE BORD'!C5 | D13: ='TABLEAU DE BORD'!F5 | E13: ='TABLEAU DE BORD'!G5 | F13: ='TABLEAU DE BORD'!J5 | G13: ='TABLEAU DE BORD'!K5 | H13: ='TABLEAU DE BORD'!H5 | I13: ='TABLEAU DE BORD'!I5 | J13: =IF('TABLEAU DE BORD'!K5="!! RUPTURE","1 — CRITIQUE",IF('TABLEAU DE BORD'!K5=">> COMMANDER","2 — URGENT",IF('TABLEAU DE BORD'!K5="~ ALERTE","3 — ATTENTION","4 — Normal"))) | K13: =IF('TABLEAU DE BORD'!K5="!! RUPTURE","⛔ BLOQUER sorties — Lancer BC immédiatement",IF('TABLEAU DE BORD'!K5=">> COMMANDER","📋 Émettre BC maintenant (stock ≤ ROP)",IF('TABLEAU DE BORD'!K5="~ ALERTE","⚠ Surveiller — préparer commande sous 3 jours","✔ Aucune action requise")))
A14: ='TABLEAU DE BORD'!A6 | B14: ='TABLEAU DE BORD'!B6 | C14: ='TABLEAU DE BORD'!C6 | D14: ='TABLEAU DE BORD'!F6 | E14: ='TABLEAU DE BORD'!G6 | F14: ='TABLEAU DE BORD'!J6 | G14: ='TABLEAU DE BORD'!K6 | H14: ='TABLEAU DE BORD'!H6 | I14: ='TABLEAU DE BORD'!I6 | J14: =IF('TABLEAU DE BORD'!K6="!! RUPTURE","1 — CRITIQUE",IF('TABLEAU DE BORD'!K6=">> COMMANDER","2 — URGENT",IF('TABLEAU DE BORD'!K6="~ ALERTE","3 — ATTENTION","4 — Normal"))) | K14: =IF('TABLEAU DE BORD'!K6="!! RUPTURE","⛔ BLOQUER sorties — Lancer BC immédiatement",IF('TABLEAU DE BORD'!K6=">> COMMANDER","📋 Émettre BC maintenant (stock ≤ ROP)",IF('TABLEAU DE BORD'!K6="~ ALERTE","⚠ Surveiller — préparer commande sous 3 jours","✔ Aucune action requise")))
A15: ='TABLEAU DE BORD'!A7 | B15: ='TABLEAU DE BORD'!B7 | C15: ='TABLEAU DE BORD'!C7 | D15: ='TABLEAU DE BORD'!F7 | E15: ='TABLEAU DE BORD'!G7 | F15: ='TABLEAU DE BORD'!J7 | G15: ='TABLEAU DE BORD'!K7 | H15: ='TABLEAU DE BORD'!H7 | I15: ='TABLEAU DE BORD'!I7 | J15: =IF('TABLEAU DE BORD'!K7="!! RUPTURE","1 — CRITIQUE",IF('TABLEAU DE BORD'!K7=">> COMMANDER","2 — URGENT",IF('TABLEAU DE BORD'!K7="~ ALERTE","3 — ATTENTION","4 — Normal"))) | K15: =IF('TABLEAU DE BORD'!K7="!! RUPTURE","⛔ BLOQUER sorties — Lancer BC immédiatement",IF('TABLEAU DE BORD'!K7=">> COMMANDER","📋 Émettre BC maintenant (stock ≤ ROP)",IF('TABLEAU DE BORD'!K7="~ ALERTE","⚠ Surveiller — préparer commande sous 3 jours","✔ Aucune action requise")))
A16: ='TABLEAU DE BORD'!A8 | B16: ='TABLEAU DE BORD'!B8 | C16: ='TABLEAU DE BORD'!C8 | D16: ='TABLEAU DE BORD'!F8 | E16: ='TABLEAU DE BORD'!G8 | F16: ='TABLEAU DE BORD'!J8 | G16: ='TABLEAU DE BORD'!K8 | H16: ='TABLEAU DE BORD'!H8 | I16: ='TABLEAU DE BORD'!I8 | J16: =IF('TABLEAU DE BORD'!K8="!! RUPTURE","1 — CRITIQUE",IF('TABLEAU DE BORD'!K8=">> COMMANDER","2 — URGENT",IF('TABLEAU DE BORD'!K8="~ ALERTE","3 — ATTENTION","4 — Normal"))) | K16: =IF('TABLEAU DE BORD'!K8="!! RUPTURE","⛔ BLOQUER sorties — Lancer BC immédiatement",IF('TABLEAU DE BORD'!K8=">> COMMANDER","📋 Émettre BC maintenant (stock ≤ ROP)",IF('TABLEAU DE BORD'!K8="~ ALERTE","⚠ Surveiller — préparer commande sous 3 jours","✔ Aucune action requise")))
A17: ='TABLEAU DE BORD'!A9 | B17: ='TABLEAU DE BORD'!B9 | C17: ='TABLEAU DE BORD'!C9 | D17: ='TABLEAU DE BORD'!F9 | E17: ='TABLEAU DE BORD'!G9 | F17: ='TABLEAU DE BORD'!J9 | G17: ='TABLEAU DE BORD'!K9 | H17: ='TABLEAU DE BORD'!H9 | I17: ='TABLEAU DE BORD'!I9 | J17: =IF('TABLEAU DE BORD'!K9="!! RUPTURE","1 — CRITIQUE",IF('TABLEAU DE BORD'!K9=">> COMMANDER","2 — URGENT",IF('TABLEAU DE BORD'!K9="~ ALERTE","3 — ATTENTION","4 — Normal"))) | K17: =IF('TABLEAU DE BORD'!K9="!! RUPTURE","⛔ BLOQUER sorties — Lancer BC immédiatement",IF('TABLEAU DE BORD'!K9=">> COMMANDER","📋 Émettre BC maintenant (stock ≤ ROP)",IF('TABLEAU DE BORD'!K9="~ ALERTE","⚠ Surveiller — préparer commande sous 3 jours","✔ Aucune action requise")))
A18: ='TABLEAU DE BORD'!A10 | B18: ='TABLEAU DE BORD'!B10 | C18: ='TABLEAU DE BORD'!C10 | D18: ='TABLEAU DE BORD'!F10 | E18: ='TABLEAU DE BORD'!G10 | F18: ='TABLEAU DE BORD'!J10 | G18: ='TABLEAU DE BORD'!K10 | H18: ='TABLEAU DE BORD'!H10 | I18: ='TABLEAU DE BORD'!I10 | J18: =IF('TABLEAU DE BORD'!K10="!! RUPTURE","1 — CRITIQUE",IF('TABLEAU DE BORD'!K10=">> COMMANDER","2 — URGENT",IF('TABLEAU DE BORD'!K10="~ ALERTE","3 — ATTENTION","4 — Normal"))) | K18: =IF('TABLEAU DE BORD'!K10="!! RUPTURE","⛔ BLOQUER sorties — Lancer BC immédiatement",IF('TABLEAU DE BORD'!K10=">> COMMANDER","📋 Émettre BC maintenant (stock ≤ ROP)",IF('TABLEAU DE BORD'!K10="~ ALERTE","⚠ Surveiller — préparer commande sous 3 jours","✔ Aucune action requise")))
A19: ='TABLEAU DE BORD'!A11 | B19: ='TABLEAU DE BORD'!B11 | C19: ='TABLEAU DE BORD'!C11 | D19: ='TABLEAU DE BORD'!F11 | E19: ='TABLEAU DE BORD'!G11 | F19: ='TABLEAU DE BORD'!J11 | G19: ='TABLEAU DE BORD'!K11 | H19: ='TABLEAU DE BORD'!H11 | I19: ='TABLEAU DE BORD'!I11 | J19: =IF('TABLEAU DE BORD'!K11="!! RUPTURE","1 — CRITIQUE",IF('TABLEAU DE BORD'!K11=">> COMMANDER","2 — URGENT",IF('TABLEAU DE BORD'!K11="~ ALERTE","3 — ATTENTION","4 — Normal"))) | K19: =IF('TABLEAU DE BORD'!K11="!! RUPTURE","⛔ BLOQUER sorties — Lancer BC immédiatement",IF('TABLEAU DE BORD'!K11=">> COMMANDER","📋 Émettre BC maintenant (stock ≤ ROP)",IF('TABLEAU DE BORD'!K11="~ ALERTE","⚠ Surveiller — préparer commande sous 3 jours","✔ Aucune action requise")))
A20: ='TABLEAU DE BORD'!A12 | B20: ='TABLEAU DE BORD'!B12 | C20: ='TABLEAU DE BORD'!C12 | D20: ='TABLEAU DE BORD'!F12 | E20: ='TABLEAU DE BORD'!G12 | F20: ='TABLEAU DE BORD'!J12 | G20: ='TABLEAU DE BORD'!K12 | H20: ='TABLEAU DE BORD'!H12 | I20: ='TABLEAU DE BORD'!I12 | J20: =IF('TABLEAU DE BORD'!K12="!! RUPTURE","1 — CRITIQUE",IF('TABLEAU DE BORD'!K12=">> COMMANDER","2 — URGENT",IF('TABLEAU DE BORD'!K12="~ ALERTE","3 — ATTENTION","4 — Normal"))) | K20: =IF('TABLEAU DE BORD'!K12="!! RUPTURE","⛔ BLOQUER sorties — Lancer BC immédiatement",IF('TABLEAU DE BORD'!K12=">> COMMANDER","📋 Émettre BC maintenant (stock ≤ ROP)",IF('TABLEAU DE BORD'!K12="~ ALERTE","⚠ Surveiller — préparer commande sous 3 jours","✔ Aucune action requise")))
A21: ='TABLEAU DE BORD'!A13 | B21: ='TABLEAU DE BORD'!B13 | C21: ='TABLEAU DE BORD'!C13 | D21: ='TABLEAU DE BORD'!F13 | E21: ='TABLEAU DE BORD'!G13 | F21: ='TABLEAU DE BORD'!J13 | G21: ='TABLEAU DE BORD'!K13 | H21: ='TABLEAU DE BORD'!H13 | I21: ='TABLEAU DE BORD'!I13 | J21: =IF('TABLEAU DE BORD'!K13="!! RUPTURE","1 — CRITIQUE",IF('TABLEAU DE BORD'!K13=">> COMMANDER","2 — URGENT",IF('TABLEAU DE BORD'!K13="~ ALERTE","3 — ATTENTION","4 — Normal"))) | K21: =IF('TABLEAU DE BORD'!K13="!! RUPTURE","⛔ BLOQUER sorties — Lancer BC immédiatement",IF('TABLEAU DE BORD'!K13=">> COMMANDER","📋 Émettre BC maintenant (stock ≤ ROP)",IF('TABLEAU DE BORD'!K13="~ ALERTE","⚠ Surveiller — préparer commande sous 3 jours","✔ Aucune action requise")))
A22: ='TABLEAU DE BORD'!A14 | B22: ='TABLEAU DE BORD'!B14 | C22: ='TABLEAU DE BORD'!C14 | D22: ='TABLEAU DE BORD'!F14 | E22: ='TABLEAU DE BORD'!G14 | F22: ='TABLEAU DE BORD'!J14 | G22: ='TABLEAU DE BORD'!K14 | H22: ='TABLEAU DE BORD'!H14 | I22: ='TABLEAU DE BORD'!I14 | J22: =IF('TABLEAU DE BORD'!K14="!! RUPTURE","1 — CRITIQUE",IF('TABLEAU DE BORD'!K14=">> COMMANDER","2 — URGENT",IF('TABLEAU DE BORD'!K14="~ ALERTE","3 — ATTENTION","4 — Normal"))) | K22: =IF('TABLEAU DE BORD'!K14="!! RUPTURE","⛔ BLOQUER sorties — Lancer BC immédiatement",IF('TABLEAU DE BORD'!K14=">> COMMANDER","📋 Émettre BC maintenant (stock ≤ ROP)",IF('TABLEAU DE BORD'!K14="~ ALERTE","⚠ Surveiller — préparer commande sous 3 jours","✔ Aucune action requise")))
A23: ='TABLEAU DE BORD'!A15 | B23: ='TABLEAU DE BORD'!B15 | C23: ='TABLEAU DE BORD'!C15 | D23: ='TABLEAU DE BORD'!F15 | E23: ='TABLEAU DE BORD'!G15 | F23: ='TABLEAU DE BORD'!J15 | G23: ='TABLEAU DE BORD'!K15 | H23: ='TABLEAU DE BORD'!H15 | I23: ='TABLEAU DE BORD'!I15 | J23: =IF('TABLEAU DE BORD'!K15="!! RUPTURE","1 — CRITIQUE",IF('TABLEAU DE BORD'!K15=">> COMMANDER","2 — URGENT",IF('TABLEAU DE BORD'!K15="~ ALERTE","3 — ATTENTION","4 — Normal"))) | K23: =IF('TABLEAU DE BORD'!K15="!! RUPTURE","⛔ BLOQUER sorties — Lancer BC immédiatement",IF('TABLEAU DE BORD'!K15=">> COMMANDER","📋 Émettre BC maintenant (stock ≤ ROP)",IF('TABLEAU DE BORD'!K15="~ ALERTE","⚠ Surveiller — préparer commande sous 3 jours","✔ Aucune action requise")))
A25: 📌 Ce tableau se recalcule automatiquement. Pour forcer: ALT+F8 → RafraichirTableauBord | Pour envoyer alerte MsgBox: ALT+F8 → VerifierAlertes

Sheet INVENTAIRE
A1: INVENTAIRE PERMANENT — Écart Physique vs Comptable [Jrد الدائم]
A2: Code | B2: Désignation | C2: Stock Comptable (Depuis MOUVEMENTS) | D2: Stock Physique (Saisie manuelle) | E2: Écart (Physique − Comptable) | F2: % Écart | G2: Statut
A3: ART-001 | B3: =IFERROR(VLOOKUP(A3,ARTICLES!$A$3:$B$500,2,0),"") | C3: =SUMIFS(MOUVEMENTS!$E$3:$E$500,MOUVEMENTS!$B$3:$B$500,A3,MOUVEMENTS!$D$3:$D$500,"IN")-SUMIFS(MOUVEMENTS!$E$3:$E$500,MOUVEMENTS!$B$3:$B$500,A3,MOUVEMENTS!$D$3:$D$500,"OUT") | E3: =IFERROR(D3-C3,"—") | F3: =IFERROR(E3/C3,"—") | G3: =IF(D3="","⏳ À compter",IF(E3=0,"✔ Conforme",IF(ABS(E3)>0,"⚠ Écart","—")))
A4: ART-002 | B4: =IFERROR(VLOOKUP(A4,ARTICLES!$A$3:$B$500,2,0),"") | C4: =SUMIFS(MOUVEMENTS!$E$3:$E$500,MOUVEMENTS!$B$3:$B$500,A4,MOUVEMENTS!$D$3:$D$500,"IN")-SUMIFS(MOUVEMENTS!$E$3:$E$500,MOUVEMENTS!$B$3:$B$500,A4,MOUVEMENTS!$D$3:$D$500,"OUT") | E4: =IFERROR(D4-C4,"—") | F4: =IFERROR(E4/C4,"—") | G4: =IF(D4="","⏳ À compter",IF(E4=0,"✔ Conforme",IF(ABS(E4)>0,"⚠ Écart","—")))
A5: ART-003 | B5: =IFERROR(VLOOKUP(A5,ARTICLES!$A$3:$B$500,2,0),"") | C5: =SUMIFS(MOUVEMENTS!$E$3:$E$500,MOUVEMENTS!$B$3:$B$500,A5,MOUVEMENTS!$D$3:$D$500,"IN")-SUMIFS(MOUVEMENTS!$E$3:$E$500,MOUVEMENTS!$B$3:$B$500,A5,MOUVEMENTS!$D$3:$D$500,"OUT") | E5: =IFERROR(D5-C5,"—") | F5: =IFERROR(E5/C5,"—") | G5: =IF(D5="","⏳ À compter",IF(E5=0,"✔ Conforme",IF(ABS(E5)>0,"⚠ Écart","—")))
A6: ART-004 | B6: =IFERROR(VLOOKUP(A6,ARTICLES!$A$3:$B$500,2,0),"") | C6: =SUMIFS(MOUVEMENTS!$E$3:$E$500,MOUVEMENTS!$B$3:$B$500,A6,MOUVEMENTS!$D$3:$D$500,"IN")-SUMIFS(MOUVEMENTS!$E$3:$E$500,MOUVEMENTS!$B$3:$B$500,A6,MOUVEMENTS!$D$3:$D$500,"OUT") | E6: =IFERROR(D6-C6,"—") | F6: =IFERROR(E6/C6,"—") | G6: =IF(D6="","⏳ À compter",IF(E6=0,"✔ Conforme",IF(ABS(E6)>0,"⚠ Écart","—")))
A7: ART-005 | B7: =IFERROR(VLOOKUP(A7,ARTICLES!$A$3:$B$500,2,0),"") | C7: =SUMIFS(MOUVEMENTS!$E$3:$E$500,MOUVEMENTS!$B$3:$B$500,A7,MOUVEMENTS!$D$3:$D$500,"IN")-SUMIFS(MOUVEMENTS!$E$3:$E$500,MOUVEMENTS!$B$3:$B$500,A7,MOUVEMENTS!$D$3:$D$500,"OUT") | E7: =IFERROR(D7-C7,"—") | F7: =IFERROR(E7/C7,"—") | G7: =IF(D7="","⏳ À compter",IF(E7=0,"✔ Conforme",IF(ABS(E7)>0,"⚠ Écart","—")))
A8: ART-006 | B8: =IFERROR(VLOOKUP(A8,ARTICLES!$A$3:$B$500,2,0),"") | C8: =SUMIFS(MOUVEMENTS!$E$3:$E$500,MOUVEMENTS!$B$3:$B$500,A8,MOUVEMENTS!$D$3:$D$500,"IN")-SUMIFS(MOUVEMENTS!$E$3:$E$500,MOUVEMENTS!$B$3:$B$500,A8,MOUVEMENTS!$D$3:$D$500,"OUT") | E8: =IFERROR(D8-C8,"—") | F8: =IFERROR(E8/C8,"—") | G8: =IF(D8="","⏳ À compter",IF(E8=0,"✔ Conforme",IF(ABS(E8)>0,"⚠ Écart","—")))
A9: ART-007 | B9: =IFERROR(VLOOKUP(A9,ARTICLES!$A$3:$B$500,2,0),"") | C9: =SUMIFS(MOUVEMENTS!$E$3:$E$500,MOUVEMENTS!$B$3:$B$500,A9,MOUVEMENTS!$D$3:$D$500,"IN")-SUMIFS(MOUVEMENTS!$E$3:$E$500,MOUVEMENTS!$B$3:$B$500,A9,MOUVEMENTS!$D$3:$D$500,"OUT") | E9: =IFERROR(D9-C9,"—") | F9: =IFERROR(E9/C9,"—") | G9: =IF(D9="","⏳ À compter",IF(E9=0,"✔ Conforme",IF(ABS(E9)>0,"⚠ Écart","—")))
A10: ART-008 | B10: =IFERROR(VLOOKUP(A10,ARTICLES!$A$3:$B$500,2,0),"") | C10: =SUMIFS(MOUVEMENTS!$E$3:$E$500,MOUVEMENTS!$B$3:$B$500,A10,MOUVEMENTS!$D$3:$D$500,"IN")-SUMIFS(MOUVEMENTS!$E$3:$E$500,MOUVEMENTS!$B$3:$B$500,A10,MOUVEMENTS!$D$3:$D$500,"OUT") | E10: =IFERROR(D10-C10,"—") | F10: =IFERROR(E10/C10,"—") | G10: =IF(D10="","⏳ À compter",IF(E10=0,"✔ Conforme",IF(ABS(E10)>0,"⚠ Écart","—")))
A11: ART-009 | B11: =IFERROR(VLOOKUP(A11,ARTICLES!$A$3:$B$500,2,0),"") | C11: =SUMIFS(MOUVEMENTS!$E$3:$E$500,MOUVEMENTS!$B$3:$B$500,A11,MOUVEMENTS!$D$3:$D$500,"IN")-SUMIFS(MOUVEMENTS!$E$3:$E$500,MOUVEMENTS!$B$3:$B$500,A11,MOUVEMENTS!$D$3:$D$500,"OUT") | E11: =IFERROR(D11-C11,"—") | F11: =IFERROR(E11/C11,"—") | G11: =IF(D11="","⏳ À compter",IF(E11=0,"✔ Conforme",IF(ABS(E11)>0,"⚠ Écart","—")))
A12: ART-010 | B12: =IFERROR(VLOOKUP(A12,ARTICLES!$A$3:$B$500,2,0),"") | C12: =SUMIFS(MOUVEMENTS!$E$3:$E$500,MOUVEMENTS!$B$3:$B$500,A12,MOUVEMENTS!$D$3:$D$500,"IN")-SUMIFS(MOUVEMENTS!$E$3:$E$500,MOUVEMENTS!$B$3:$B$500,A12,MOUVEMENTS!$D$3:$D$500,"OUT") | E12: =IFERROR(D12-C12,"—") | F12: =IFERROR(E12/C12,"—") | G12: =IF(D12="","⏳ À compter",IF(E12=0,"✔ Conforme",IF(ABS(E12)>0,"⚠ Écart","—")))
A13: ART-011 | B13: =IFERROR(VLOOKUP(A13,ARTICLES!$A$3:$B$500,2,0),"") | C13: =SUMIFS(MOUVEMENTS!$E$3:$E$500,MOUVEMENTS!$B$3:$B$500,A13,MOUVEMENTS!$D$3:$D$500,"IN")-SUMIFS(MOUVEMENTS!$E$3:$E$500,MOUVEMENTS!$B$3:$B$500,A13,MOUVEMENTS!$D$3:$D$500,"OUT") | E13: =IFERROR(D13-C13,"—") | F13: =IFERROR(E13/C13,"—") | G13: =IF(D13="","⏳ À compter",IF(E13=0,"✔ Conforme",IF(ABS(E13)>0,"⚠ Écart","—")))
A14: ART-012 | B14: =IFERROR(VLOOKUP(A14,ARTICLES!$A$3:$B$500,2,0),"") | C14: =SUMIFS(MOUVEMENTS!$E$3:$E$500,MOUVEMENTS!$B$3:$B$500,A14,MOUVEMENTS!$D$3:$D$500,"IN")-SUMIFS(MOUVEMENTS!$E$3:$E$500,MOUVEMENTS!$B$3:$B$500,A14,MOUVEMENTS!$D$3:$D$500,"OUT") | E14: =IFERROR(D14-C14,"—") | F14: =IFERROR(E14/C14,"—") | G14: =IF(D14="","⏳ À compter",IF(E14=0,"✔ Conforme",IF(ABS(E14)>0,"⚠ Écart","—")))
A16: 📌 Saisir le stock physique constaté (colonne D) lors de chaque opération d'inventaire.

Sheet RAPPORTS
A1: RAPPORTS — التقارير الدورية | مخزن مديرية التربية — ولاية البيض
A2: الأرقام تُحسَب تلقائياً من ورقة MOUVEMENTS. أدخل التواريخ في الخلايا المحددة بالإطار السميك لتصفية الفترة المطلوبة.
A4: ▸ التقرير الأسبوعي — Rapport Hebdomadaire — Fréquence: chaque lundi
A5: من / Du : | C5: إلى / À : | E5: ★ أدخل تواريخ الفترة في الخلايا B و D
A6: رمز المادة | B6: التسمية | C6: الفئة | D6: دخول (IN) | E6: خروج (OUT) | F6: الرصيد (Net) | G6: القيمة (DA) | H6: ملاحظة
A7: ART-001 | B7: =IFERROR(VLOOKUP(A7,ARTICLES!$A$3:$B$500,2,0),"") | C7: =IFERROR(VLOOKUP(A7,ARTICLES!$A$3:$E$500,5,0),"") | D7: =IFERROR(SUMPRODUCT((MOUVEMENTS!$B$3:$B$500=A7)*(MOUVEMENTS!$D$3:$D$500="IN")*(MOUVEMENTS!$A$3:$A$500>=B5)*(MOUVEMENTS!$A$3:$A$500<=D5)*MOUVEMENTS!$E$3:$E$500),0) | E7: =IFERROR(SUMPRODUCT((MOUVEMENTS!$B$3:$B$500=A7)*(MOUVEMENTS!$D$3:$D$500="OUT")*(MOUVEMENTS!$A$3:$A$500>=B5)*(MOUVEMENTS!$A$3:$A$500<=D5)*MOUVEMENTS!$E$3:$E$500),0) | F7: =D7-E7 | G7: =IFERROR(F7*VLOOKUP(A7,ARTICLES!$A$3:$G$500,7,0),0) | H7: =IF(F7<0,"!! NÉGATIF",IF(F7=0,"!! RUPTURE","OK"))
A8: ART-002 | B8: =IFERROR(VLOOKUP(A8,ARTICLES!$A$3:$B$500,2,0),"") | C8: =IFERROR(VLOOKUP(A8,ARTICLES!$A$3:$E$500,5,0),"") | D8: =IFERROR(SUMPRODUCT((MOUVEMENTS!$B$3:$B$500=A8)*(MOUVEMENTS!$D$3:$D$500="IN")*(MOUVEMENTS!$A$3:$A$500>=B5)*(MOUVEMENTS!$A$3:$A$500<=D5)*MOUVEMENTS!$E$3:$E$500),0) | E8: =IFERROR(SUMPRODUCT((MOUVEMENTS!$B$3:$B$500=A8)*(MOUVEMENTS!$D$3:$D$500="OUT")*(MOUVEMENTS!$A$3:$A$500>=B5)*(MOUVEMENTS!$A$3:$A$500<=D5)*MOUVEMENTS!$E$3:$E$500),0) | F8: =D8-E8 | G8: =IFERROR(F8*VLOOKUP(A8,ARTICLES!$A$3:$G$500,7,0),0) | H8: =IF(F8<0,"!! NÉGATIF",IF(F8=0,"!! RUPTURE","OK"))
A9: ART-003 | B9: =IFERROR(VLOOKUP(A9,ARTICLES!$A$3:$B$500,2,0),"") | C9: =IFERROR(VLOOKUP(A9,ARTICLES!$A$3:$E$500,5,0),"") | D9: =IFERROR(SUMPRODUCT((MOUVEMENTS!$B$3:$B$500=A9)*(MOUVEMENTS!$D$3:$D$500="IN")*(MOUVEMENTS!$A$3:$A$500>=B5)*(MOUVEMENTS!$A$3:$A$500<=D5)*MOUVEMENTS!$E$3:$E$500),0) | E9: =IFERROR(SUMPRODUCT((MOUVEMENTS!$B$3:$B$500=A9)*(MOUVEMENTS!$D$3:$D$500="OUT")*(MOUVEMENTS!$A$3:$A$500>=B5)*(MOUVEMENTS!$A$3:$A$500<=D5)*MOUVEMENTS!$E$3:$E$500),0) | F9: =D9-E9 | G9: =IFERROR(F9*VLOOKUP(A9,ARTICLES!$A$3:$G$500,7,0),0) | H9: =IF(F9<0,"!! NÉGATIF",IF(F9=0,"!! RUPTURE","OK"))
A10: ART-004 | B10: =IFERROR(VLOOKUP(A10,ARTICLES!$A$3:$B$500,2,0),"") | C10: =IFERROR(VLOOKUP(A10,ARTICLES!$A$3:$E$500,5,0),"") | D10: =IFERROR(SUMPRODUCT((MOUVEMENTS!$B$3:$B$500=A10)*(MOUVEMENTS!$D$3:$D$500="IN")*(MOUVEMENTS!$A$3:$A$500>=B5)*(MOUVEMENTS!$A$3:$A$500<=D5)*MOUVEMENTS!$E$3:$E$500),0) | E10: =IFERROR(SUMPRODUCT((MOUVEMENTS!$B$3:$B$500=A10)*(MOUVEMENTS!$D$3:$D$500="OUT")*(MOUVEMENTS!$A$3:$A$500>=B5)*(MOUVEMENTS!$A$3:$A$500<=D5)*MOUVEMENTS!$E$3:$E$500),0) | F10: =D10-E10 | G10: =IFERROR(F10*VLOOKUP(A10,ARTICLES!$A$3:$G$500,7,0),0) | H10: =IF(F10<0,"!! NÉGATIF",IF(F10=0,"!! RUPTURE","OK"))
A11: ART-005 | B11: =IFERROR(VLOOKUP(A11,ARTICLES!$A$3:$B$500,2,0),"") | C11: =IFERROR(VLOOKUP(A11,ARTICLES!$A$3:$E$500,5,0),"") | D11: =IFERROR(SUMPRODUCT((MOUVEMENTS!$B$3:$B$500=A11)*(MOUVEMENTS!$D$3:$D$500="IN")*(MOUVEMENTS!$A$3:$A$500>=B5)*(MOUVEMENTS!$A$3:$A$500<=D5)*MOUVEMENTS!$E$3:$E$500),0) | E11: =IFERROR(SUMPRODUCT((MOUVEMENTS!$B$3:$B$500=A11)*(MOUVEMENTS!$D$3:$D$500="OUT")*(MOUVEMENTS!$A$3:$A$500>=B5)*(MOUVEMENTS!$A$3:$A$500<=D5)*MOUVEMENTS!$E$3:$E$500),0) | F11: =D11-E11 | G11: =IFERROR(F11*VLOOKUP(A11,ARTICLES!$A$3:$G$500,7,0),0) | H11: =IF(F11<0,"!! NÉGATIF",IF(F11=0,"!! RUPTURE","OK"))
A12: ART-006 | B12: =IFERROR(VLOOKUP(A12,ARTICLES!$A$3:$B$500,2,0),"") | C12: =IFERROR(VLOOKUP(A12,ARTICLES!$A$3:$E$500,5,0),"") | D12: =IFERROR(SUMPRODUCT((MOUVEMENTS!$B$3:$B$500=A12)*(MOUVEMENTS!$D$3:$D$500="IN")*(MOUVEMENTS!$A$3:$A$500>=B5)*(MOUVEMENTS!$A$3:$A$500<=D5)*MOUVEMENTS!$E$3:$E$500),0) | E12: =IFERROR(SUMPRODUCT((MOUVEMENTS!$B$3:$B$500=A12)*(MOUVEMENTS!$D$3:$D$500="OUT")*(MOUVEMENTS!$A$3:$A$500>=B5)*(MOUVEMENTS!$A$3:$A$500<=D5)*MOUVEMENTS!$E$3:$E$500),0) | F12: =D12-E12 | G12: =IFERROR(F12*VLOOKUP(A12,ARTICLES!$A$3:$G$500,7,0),0) | H12: =IF(F12<0,"!! NÉGATIF",IF(F12=0,"!! RUPTURE","OK"))
A13: ART-007 | B13: =IFERROR(VLOOKUP(A13,ARTICLES!$A$3:$B$500,2,0),"") | C13: =IFERROR(VLOOKUP(A13,ARTICLES!$A$3:$E$500,5,0),"") | D13: =IFERROR(SUMPRODUCT((MOUVEMENTS!$B$3:$B$500=A13)*(MOUVEMENTS!$D$3:$D$500="IN")*(MOUVEMENTS!$A$3:$A$500>=B5)*(MOUVEMENTS!$A$3:$A$500<=D5)*MOUVEMENTS!$E$3:$E$500),0) | E13: =IFERROR(SUMPRODUCT((MOUVEMENTS!$B$3:$B$500=A13)*(MOUVEMENTS!$D$3:$D$500="OUT")*(MOUVEMENTS!$A$3:$A$500>=B5)*(MOUVEMENTS!$A$3:$A$500<=D5)*MOUVEMENTS!$E$3:$E$500),0) | F13: =D13-E13 | G13: =IFERROR(F13*VLOOKUP(A13,ARTICLES!$A$3:$G$500,7,0),0) | H13: =IF(F13<0,"!! NÉGATIF",IF(F13=0,"!! RUPTURE","OK"))
A14: ART-008 | B14: =IFERROR(VLOOKUP(A14,ARTICLES!$A$3:$B$500,2,0),"") | C14: =IFERROR(VLOOKUP(A14,ARTICLES!$A$3:$E$500,5,0),"") | D14: =IFERROR(SUMPRODUCT((MOUVEMENTS!$B$3:$B$500=A14)*(MOUVEMENTS!$D$3:$D$500="IN")*(MOUVEMENTS!$A$3:$A$500>=B5)*(MOUVEMENTS!$A$3:$A$500<=D5)*MOUVEMENTS!$E$3:$E$500),0) | E14: =IFERROR(SUMPRODUCT((MOUVEMENTS!$B$3:$B$500=A14)*(MOUVEMENTS!$D$3:$D$500="OUT")*(MOUVEMENTS!$A$3:$A$500>=B5)*(MOUVEMENTS!$A$3:$A$500<=D5)*MOUVEMENTS!$E$3:$E$500),0) | F14: =D14-E14 | G14: =IFERROR(F14*VLOOKUP(A14,ARTICLES!$A$3:$G$500,7,0),0) | H14: =IF(F14<0,"!! NÉGATIF",IF(F14=0,"!! RUPTURE","OK"))
A15: ART-009 | B15: =IFERROR(VLOOKUP(A15,ARTICLES!$A$3:$B$500,2,0),"") | C15: =IFERROR(VLOOKUP(A15,ARTICLES!$A$3:$E$500,5,0),"") | D15: =IFERROR(SUMPRODUCT((MOUVEMENTS!$B$3:$B$500=A15)*(MOUVEMENTS!$D$3:$D$500="IN")*(MOUVEMENTS!$A$3:$A$500>=B5)*(MOUVEMENTS!$A$3:$A$500<=D5)*MOUVEMENTS!$E$3:$E$500),0) | E15: =IFERROR(SUMPRODUCT((MOUVEMENTS!$B$3:$B$500=A15)*(MOUVEMENTS!$D$3:$D$500="OUT")*(MOUVEMENTS!$A$3:$A$500>=B5)*(MOUVEMENTS!$A$3:$A$500<=D5)*MOUVEMENTS!$E$3:$E$500),0) | F15: =D15-E15 | G15: =IFERROR(F15*VLOOKUP(A15,ARTICLES!$A$3:$G$500,7,0),0) | H15: =IF(F15<0,"!! NÉGATIF",IF(F15=0,"!! RUPTURE","OK"))
A16: ART-010 | B16: =IFERROR(VLOOKUP(A16,ARTICLES!$A$3:$B$500,2,0),"") | C16: =IFERROR(VLOOKUP(A16,ARTICLES!$A$3:$E$500,5,0),"") | D16: =IFERROR(SUMPRODUCT((MOUVEMENTS!$B$3:$B$500=A16)*(MOUVEMENTS!$D$3:$D$500="IN")*(MOUVEMENTS!$A$3:$A$500>=B5)*(MOUVEMENTS!$A$3:$A$500<=D5)*MOUVEMENTS!$E$3:$E$500),0) | E16: =IFERROR(SUMPRODUCT((MOUVEMENTS!$B$3:$B$500=A16)*(MOUVEMENTS!$D$3:$D$500="OUT")*(MOUVEMENTS!$A$3:$A$500>=B5)*(MOUVEMENTS!$A$3:$A$500<=D5)*MOUVEMENTS!$E$3:$E$500),0) | F16: =D16-E16 | G16: =IFERROR(F16*VLOOKUP(A16,ARTICLES!$A$3:$G$500,7,0),0) | H16: =IF(F16<0,"!! NÉGATIF",IF(F16=0,"!! RUPTURE","OK"))
A17: ART-011 | B17: =IFERROR(VLOOKUP(A17,ARTICLES!$A$3:$B$500,2,0),"") | C17: =IFERROR(VLOOKUP(A17,ARTICLES!$A$3:$E$500,5,0),"") | D17: =IFERROR(SUMPRODUCT((MOUVEMENTS!$B$3:$B$500=A17)*(MOUVEMENTS!$D$3:$D$500="IN")*(MOUVEMENTS!$A$3:$A$500>=B5)*(MOUVEMENTS!$A$3:$A$500<=D5)*MOUVEMENTS!$E$3:$E$500),0) | E17: =IFERROR(SUMPRODUCT((MOUVEMENTS!$B$3:$B$500=A17)*(MOUVEMENTS!$D$3:$D$500="OUT")*(MOUVEMENTS!$A$3:$A$500>=B5)*(MOUVEMENTS!$A$3:$A$500<=D5)*MOUVEMENTS!$E$3:$E$500),0) | F17: =D17-E17 | G17: =IFERROR(F17*VLOOKUP(A17,ARTICLES!$A$3:$G$500,7,0),0) | H17: =IF(F17<0,"!! NÉGATIF",IF(F17=0,"!! RUPTURE","OK"))
A18: ART-012 | B18: =IFERROR(VLOOKUP(A18,ARTICLES!$A$3:$B$500,2,0),"") | C18: =IFERROR(VLOOKUP(A18,ARTICLES!$A$3:$E$500,5,0),"") | D18: =IFERROR(SUMPRODUCT((MOUVEMENTS!$B$3:$B$500=A18)*(MOUVEMENTS!$D$3:$D$500="IN")*(MOUVEMENTS!$A$3:$A$500>=B5)*(MOUVEMENTS!$A$3:$A$500<=D5)*MOUVEMENTS!$E$3:$E$500),0) | E18: =IFERROR(SUMPRODUCT((MOUVEMENTS!$B$3:$B$500=A18)*(MOUVEMENTS!$D$3:$D$500="OUT")*(MOUVEMENTS!$A$3:$A$500>=B5)*(MOUVEMENTS!$A$3:$A$500<=D5)*MOUVEMENTS!$E$3:$E$500),0) | F18: =D18-E18 | G18: =IFERROR(F18*VLOOKUP(A18,ARTICLES!$A$3:$G$500,7,0),0) | H18: =IF(F18<0,"!! NÉGATIF",IF(F18=0,"!! RUPTURE","OK"))
A19: TOTAUX | B19: Total période | D19: =SUM(D7:D18) | E19: =SUM(E7:E18) | F19: =SUM(F7:F18) | G19: =SUM(G7:G18)
A20: 📌 التقرير الأسبوعي يُطبَع كل اثنين ويُسلَّم لمسؤول الوسائل. يُركِّز على مواد الفئة A (ورق A4 + حبر الطابعة).
A23: ▸ التقرير الشهري — Rapport Mensuel — Fréquence: fin de chaque mois
A24: من / Du : | C24: إلى / À : | E24: ★ أدخل تواريخ الفترة في الخلايا B و D
A25: رمز المادة | B25: التسمية | C25: الفئة | D25: دخول (IN) | E25: خروج (OUT) | F25: الرصيد (Net) | G25: القيمة (DA) | H25: ملاحظة
A26: ART-001 | B26: =IFERROR(VLOOKUP(A26,ARTICLES!$A$3:$B$500,2,0),"") | C26: =IFERROR(VLOOKUP(A26,ARTICLES!$A$3:$E$500,5,0),"") | D26: =IFERROR(SUMPRODUCT((MOUVEMENTS!$B$3:$B$500=A26)*(MOUVEMENTS!$D$3:$D$500="IN")*(MOUVEMENTS!$A$3:$A$500>=B24)*(MOUVEMENTS!$A$3:$A$500<=D24)*MOUVEMENTS!$E$3:$E$500),0) | E26: =IFERROR(SUMPRODUCT((MOUVEMENTS!$B$3:$B$500=A26)*(MOUVEMENTS!$D$3:$D$500="OUT")*(MOUVEMENTS!$A$3:$A$500>=B24)*(MOUVEMENTS!$A$3:$A$500<=D24)*MOUVEMENTS!$E$3:$E$500),0) | F26: =D26-E26 | G26: =IFERROR(F26*VLOOKUP(A26,ARTICLES!$A$3:$G$500,7,0),0) | H26: =IF(F26<0,"!! NÉGATIF",IF(F26=0,"!! RUPTURE","OK"))
A27: ART-002 | B27: =IFERROR(VLOOKUP(A27,ARTICLES!$A$3:$B$500,2,0),"") | C27: =IFERROR(VLOOKUP(A27,ARTICLES!$A$3:$E$500,5,0),"") | D27: =IFERROR(SUMPRODUCT((MOUVEMENTS!$B$3:$B$500=A27)*(MOUVEMENTS!$D$3:$D$500="IN")*(MOUVEMENTS!$A$3:$A$500>=B24)*(MOUVEMENTS!$A$3:$A$500<=D24)*MOUVEMENTS!$E$3:$E$500),0) | E27: =IFERROR(SUMPRODUCT((MOUVEMENTS!$B$3:$B$500=A27)*(MOUVEMENTS!$D$3:$D$500="OUT")*(MOUVEMENTS!$A$3:$A$500>=B24)*(MOUVEMENTS!$A$3:$A$500<=D24)*MOUVEMENTS!$E$3:$E$500),0) | F27: =D27-E27 | G27: =IFERROR(F27*VLOOKUP(A27,ARTICLES!$A$3:$G$500,7,0),0) | H27: =IF(F27<0,"!! NÉGATIF",IF(F27=0,"!! RUPTURE","OK"))
A28: ART-003 | B28: =IFERROR(VLOOKUP(A28,ARTICLES!$A$3:$B$500,2,0),"") | C28: =IFERROR(VLOOKUP(A28,ARTICLES!$A$3:$E$500,5,0),"") | D28: =IFERROR(SUMPRODUCT((MOUVEMENTS!$B$3:$B$500=A28)*(MOUVEMENTS!$D$3:$D$500="IN")*(MOUVEMENTS!$A$3:$A$500>=B24)*(MOUVEMENTS!$A$3:$A$500<=D24)*MOUVEMENTS!$E$3:$E$500),0) | E28: =IFERROR(SUMPRODUCT((MOUVEMENTS!$B$3:$B$500=A28)*(MOUVEMENTS!$D$3:$D$500="OUT")*(MOUVEMENTS!$A$3:$A$500>=B24)*(MOUVEMENTS!$A$3:$A$500<=D24)*MOUVEMENTS!$E$3:$E$500),0) | F28: =D28-E28 | G28: =IFERROR(F28*VLOOKUP(A28,ARTICLES!$A$3:$G$500,7,0),0) | H28: =IF(F28<0,"!! NÉGATIF",IF(F28=0,"!! RUPTURE","OK"))
A29: ART-004 | B29: =IFERROR(VLOOKUP(A29,ARTICLES!$A$3:$B$500,2,0),"") | C29: =IFERROR(VLOOKUP(A29,ARTICLES!$A$3:$E$500,5,0),"") | D29: =IFERROR(SUMPRODUCT((MOUVEMENTS!$B$3:$B$500=A29)*(MOUVEMENTS!$D$3:$D$500="IN")*(MOUVEMENTS!$A$3:$A$500>=B24)*(MOUVEMENTS!$A$3:$A$500<=D24)*MOUVEMENTS!$E$3:$E$500),0) | E29: =IFERROR(SUMPRODUCT((MOUVEMENTS!$B$3:$B$500=A29)*(MOUVEMENTS!$D$3:$D$500="OUT")*(MOUVEMENTS!$A$3:$A$500>=B24)*(MOUVEMENTS!$A$3:$A$500<=D24)*MOUVEMENTS!$E$3:$E$500),0) | F29: =D29-E29 | G29: =IFERROR(F29*VLOOKUP(A29,ARTICLES!$A$3:$G$500,7,0),0) | H29: =IF(F29<0,"!! NÉGATIF",IF(F29=0,"!! RUPTURE","OK"))
A30: ART-005 | B30: =IFERROR(VLOOKUP(A30,ARTICLES!$A$3:$B$500,2,0),"") | C30: =IFERROR(VLOOKUP(A30,ARTICLES!$A$3:$E$500,5,0),"") | D30: =IFERROR(SUMPRODUCT((MOUVEMENTS!$B$3:$B$500=A30)*(MOUVEMENTS!$D$3:$D$500="IN")*(MOUVEMENTS!$A$3:$A$500>=B24)*(MOUVEMENTS!$A$3:$A$500<=D24)*MOUVEMENTS!$E$3:$E$500),0) | E30: =IFERROR(SUMPRODUCT((MOUVEMENTS!$B$3:$B$500=A30)*(MOUVEMENTS!$D$3:$D$500="OUT")*(MOUVEMENTS!$A$3:$A$500>=B24)*(MOUVEMENTS!$A$3:$A$500<=D24)*MOUVEMENTS!$E$3:$E$500),0) | F30: =D30-E30 | G30: =IFERROR(F30*VLOOKUP(A30,ARTICLES!$A$3:$G$500,7,0),0) | H30: =IF(F30<0,"!! NÉGATIF",IF(F30=0,"!! RUPTURE","OK"))
A31: ART-006 | B31: =IFERROR(VLOOKUP(A31,ARTICLES!$A$3:$B$500,2,0),"") | C31: =IFERROR(VLOOKUP(A31,ARTICLES!$A$3:$E$500,5,0),"") | D31: =IFERROR(SUMPRODUCT((MOUVEMENTS!$B$3:$B$500=A31)*(MOUVEMENTS!$D$3:$D$500="IN")*(MOUVEMENTS!$A$3:$A$500>=B24)*(MOUVEMENTS!$A$3:$A$500<=D24)*MOUVEMENTS!$E$3:$E$500),0) | E31: =IFERROR(SUMPRODUCT((MOUVEMENTS!$B$3:$B$500=A31)*(MOUVEMENTS!$D$3:$D$500="OUT")*(MOUVEMENTS!$A$3:$A$500>=B24)*(MOUVEMENTS!$A$3:$A$500<=D24)*MOUVEMENTS!$E$3:$E$500),0) | F31: =D31-E31 | G31: =IFERROR(F31*VLOOKUP(A31,ARTICLES!$A$3:$G$500,7,0),0) | H31: =IF(F31<0,"!! NÉGATIF",IF(F31=0,"!! RUPTURE","OK"))
A32: ART-007 | B32: =IFERROR(VLOOKUP(A32,ARTICLES!$A$3:$B$500,2,0),"") | C32: =IFERROR(VLOOKUP(A32,ARTICLES!$A$3:$E$500,5,0),"") | D32: =IFERROR(SUMPRODUCT((MOUVEMENTS!$B$3:$B$500=A32)*(MOUVEMENTS!$D$3:$D$500="IN")*(MOUVEMENTS!$A$3:$A$500>=B24)*(MOUVEMENTS!$A$3:$A$500<=D24)*MOUVEMENTS!$E$3:$E$500),0) | E32: =IFERROR(SUMPRODUCT((MOUVEMENTS!$B$3:$B$500=A32)*(MOUVEMENTS!$D$3:$D$500="OUT")*(MOUVEMENTS!$A$3:$A$500>=B24)*(MOUVEMENTS!$A$3:$A$500<=D24)*MOUVEMENTS!$E$3:$E$500),0) | F32: =D32-E32 | G32: =IFERROR(F32*VLOOKUP(A32,ARTICLES!$A$3:$G$500,7,0),0) | H32: =IF(F32<0,"!! NÉGATIF",IF(F32=0,"!! RUPTURE","OK"))
A33: ART-008 | B33: =IFERROR(VLOOKUP(A33,ARTICLES!$A$3:$B$500,2,0),"") | C33: =IFERROR(VLOOKUP(A33,ARTICLES!$A$3:$E$500,5,0),"") | D33: =IFERROR(SUMPRODUCT((MOUVEMENTS!$B$3:$B$500=A33)*(MOUVEMENTS!$D$3:$D$500="IN")*(MOUVEMENTS!$A$3:$A$500>=B24)*(MOUVEMENTS!$A$3:$A$500<=D24)*MOUVEMENTS!$E$3:$E$500),0) | E33: =IFERROR(SUMPRODUCT((MOUVEMENTS!$B$3:$B$500=A33)*(MOUVEMENTS!$D$3:$D$500="OUT")*(MOUVEMENTS!$A$3:$A$500>=B24)*(MOUVEMENTS!$A$3:$A$500<=D24)*MOUVEMENTS!$E$3:$E$500),0) | F33: =D33-E33 | G33: =IFERROR(F33*VLOOKUP(A33,ARTICLES!$A$3:$G$500,7,0),0) | H33: =IF(F33<0,"!! NÉGATIF",IF(F33=0,"!! RUPTURE","OK"))
A34: ART-009 | B34: =IFERROR(VLOOKUP(A34,ARTICLES!$A$3:$B$500,2,0),"") | C34: =IFERROR(VLOOKUP(A34,ARTICLES!$A$3:$E$500,5,0),"") | D34: =IFERROR(SUMPRODUCT((MOUVEMENTS!$B$3:$B$500=A34)*(MOUVEMENTS!$D$3:$D$500="IN")*(MOUVEMENTS!$A$3:$A$500>=B24)*(MOUVEMENTS!$A$3:$A$500<=D24)*MOUVEMENTS!$E$3:$E$500),0) | E34: =IFERROR(SUMPRODUCT((MOUVEMENTS!$B$3:$B$500=A34)*(MOUVEMENTS!$D$3:$D$500="OUT")*(MOUVEMENTS!$A$3:$A$500>=B24)*(MOUVEMENTS!$A$3:$A$500<=D24)*MOUVEMENTS!$E$3:$E$500),0) | F34: =D34-E34 | G34: =IFERROR(F34*VLOOKUP(A34,ARTICLES!$A$3:$G$500,7,0),0) | H34: =IF(F34<0,"!! NÉGATIF",IF(F34=0,"!! RUPTURE","OK"))
A35: ART-010 | B35: =IFERROR(VLOOKUP(A35,ARTICLES!$A$3:$B$500,2,0),"") | C35: =IFERROR(VLOOKUP(A35,ARTICLES!$A$3:$E$500,5,0),"") | D35: =IFERROR(SUMPRODUCT((MOUVEMENTS!$B$3:$B$500=A35)*(MOUVEMENTS!$D$3:$D$500="IN")*(MOUVEMENTS!$A$3:$A$500>=B24)*(MOUVEMENTS!$A$3:$A$500<=D24)*MOUVEMENTS!$E$3:$E$500),0) | E35: =IFERROR(SUMPRODUCT((MOUVEMENTS!$B$3:$B$500=A35)*(MOUVEMENTS!$D$3:$D$500="OUT")*(MOUVEMENTS!$A$3:$A$500>=B24)*(MOUVEMENTS!$A$3:$A$500<=D24)*MOUVEMENTS!$E$3:$E$500),0) | F35: =D35-E35 | G35: =IFERROR(F35*VLOOKUP(A35,ARTICLES!$A$3:$G$500,7,0),0) | H35: =IF(F35<0,"!! NÉGATIF",IF(F35=0,"!! RUPTURE","OK"))
A36: ART-011 | B36: =IFERROR(VLOOKUP(A36,ARTICLES!$A$3:$B$500,2,0),"") | C36: =IFERROR(VLOOKUP(A36,ARTICLES!$A$3:$E$500,5,0),"") | D36: =IFERROR(SUMPRODUCT((MOUVEMENTS!$B$3:$B$500=A36)*(MOUVEMENTS!$D$3:$D$500="IN")*(MOUVEMENTS!$A$3:$A$500>=B24)*(MOUVEMENTS!$A$3:$A$500<=D24)*MOUVEMENTS!$E$3:$E$500),0) | E36: =IFERROR(SUMPRODUCT((MOUVEMENTS!$B$3:$B$500=A36)*(MOUVEMENTS!$D$3:$D$500="OUT")*(MOUVEMENTS!$A$3:$A$500>=B24)*(MOUVEMENTS!$A$3:$A$500<=D24)*MOUVEMENTS!$E$3:$E$500),0) | F36: =D36-E36 | G36: =IFERROR(F36*VLOOKUP(A36,ARTICLES!$A$3:$G$500,7,0),0) | H36: =IF(F36<0,"!! NÉGATIF",IF(F36=0,"!! RUPTURE","OK"))
A37: ART-012 | B37: =IFERROR(VLOOKUP(A37,ARTICLES!$A$3:$B$500,2,0),"") | C37: =IFERROR(VLOOKUP(A37,ARTICLES!$A$3:$E$500,5,0),"") | D37: =IFERROR(SUMPRODUCT((MOUVEMENTS!$B$3:$B$500=A37)*(MOUVEMENTS!$D$3:$D$500="IN")*(MOUVEMENTS!$A$3:$A$500>=B24)*(MOUVEMENTS!$A$3:$A$500<=D24)*MOUVEMENTS!$E$3:$E$500),0) | E37: =IFERROR(SUMPRODUCT((MOUVEMENTS!$B$3:$B$500=A37)*(MOUVEMENTS!$D$3:$D$500="OUT")*(MOUVEMENTS!$A$3:$A$500>=B24)*(MOUVEMENTS!$A$3:$A$500<=D24)*MOUVEMENTS!$E$3:$E$500),0) | F37: =D37-E37 | G37: =IFERROR(F37*VLOOKUP(A37,ARTICLES!$A$3:$G$500,7,0),0) | H37: =IF(F37<0,"!! NÉGATIF",IF(F37=0,"!! RUPTURE","OK"))
A38: TOTAUX | B38: Total période | D38: =SUM(D26:D37) | E38: =SUM(E26:E37) | F38: =SUM(F26:F37) | G38: =SUM(G26:G37)
A39: 📌 التقرير الشهري يُقدَّم لمصلحة الميزانية. يُقارَن رصيد نهاية الشهر بالرصيد الافتتاحي لقياس معدل الاستهلاك.
A42: ▸ التقرير الفصلي (3 أشهر) — Rapport Trimestriel — Fréquence: janv / avr / juil / oct
A43: من / Du : | C43: إلى / À : | E43: ★ أدخل تواريخ الفترة في الخلايا B و D
A44: رمز المادة | B44: التسمية | C44: الفئة | D44: دخول (IN) | E44: خروج (OUT) | F44: الرصيد (Net) | G44: القيمة (DA) | H44: ملاحظة
A45: ART-001 | B45: =IFERROR(VLOOKUP(A45,ARTICLES!$A$3:$B$500,2,0),"") | C45: =IFERROR(VLOOKUP(A45,ARTICLES!$A$3:$E$500,5,0),"") | D45: =IFERROR(SUMPRODUCT((MOUVEMENTS!$B$3:$B$500=A45)*(MOUVEMENTS!$D$3:$D$500="IN")*(MOUVEMENTS!$A$3:$A$500>=B43)*(MOUVEMENTS!$A$3:$A$500<=D43)*MOUVEMENTS!$E$3:$E$500),0) | E45: =IFERROR(SUMPRODUCT((MOUVEMENTS!$B$3:$B$500=A45)*(MOUVEMENTS!$D$3:$D$500="OUT")*(MOUVEMENTS!$A$3:$A$500>=B43)*(MOUVEMENTS!$A$3:$A$500<=D43)*MOUVEMENTS!$E$3:$E$500),0) | F45: =D45-E45 | G45: =IFERROR(F45*VLOOKUP(A45,ARTICLES!$A$3:$G$500,7,0),0) | H45: =IF(F45<0,"!! NÉGATIF",IF(F45=0,"!! RUPTURE","OK"))
...

Sheet CALCULS_EOQ
A1: MODÈLE DE WILSON — EOQ [OPT-03 | D Auto-annualisé | ART-001 | Excel 2010]
A3: D | B3: Demande annuelle ART-001 [AUTO annualisé ×250 j] | C3: =ROUND(SUMPRODUCT((MOUVEMENTS!$B$3:$B$500="ART-001")*(MOUVEMENTS!$D$3:$D$500="OUT")*MOUVEMENTS!$E$3:$E$500)/38*250,0) | D3: unités/an
A4: CL | B4: Coût passation par commande (DA) [modifiable] | C4: 50 | D4: DA/cmd
A5: PU | B5: Prix unitaire ART-001 (DA) [confirmé terrain] | C5: 400 | D5: DA/rame
A6: t | B6: Taux de possession annuel | C6: 0.2 | D6: %
A7: SS | B7: Stock de sécurité (unités) [modifiable] | C7: 200 | D7: unités
A8: LT | B8: Délai livraison Oran→Bayadh (jours ouvrés) | C8: 2 | D8: jours
A10: RÉSULTATS DU MODÈLE — Q*, N, ROP, CVT
A11: EOQ | B11: Quantité économique Q* = √(2·D·CL / Cs) où Cs = PU·t | C11: =ROUND(SQRT(2*C3*C4/(C6*C5)),0) | D11: unités
A12: N | B12: Nombre de commandes par an N = D / Q* | C12: =ROUND(C3/C11,1) | D12: cmd/an
A13: ROP | B13: Point de réappro ROP = SS + CMJ·LT [CMJ=D/250] | C13: =ROUND(C7+(C3/250)*C8,0) | D13: unités
A14: Cp | B14: Coût de passation annuel Cp = (D/Q*)·CL | C14: =ROUND((C3/C11)*C4,0) | D14: DA/an
